<?xml version="1.0" ?>
<!-- =================================================================================== -->
<!-- |    This document was autogenerated by xacro from tiago.urdf.xacro               | -->
<!-- |    EDITING THIS FILE BY HAND IS NOT RECOMMENDED                                 | -->
<!-- =================================================================================== -->
<!--
  Copyright (c) 2011, PAL Robotics, S.L.
  All rights reserved.

  This work is licensed under the Creative Commons Attribution-NonCommercial-NoDerivs 3.0 Unported License.
  To view a copy of this license, visit http://creativecommons.org/licenses/by-nc-nd/3.0/ or send a letter to
  Creative Commons, 444 Castro Street, Suite 900, Mountain View, California, 94041, USA.
-->
<robot name="tiago">
  <material name="Blue">
    <color rgba="0.0 0.0 0.8 1.0"/>
  </material>
  <material name="Green">
    <color rgba="0.0 0.8 0.0 1.0"/>
  </material>
  <material name="Grey">
    <color rgba="0.7 0.7 0.7 1.0"/>
  </material>
  <material name="LightGrey">
    <color rgba="0.9 0.9 0.9 1.0"/>
  </material>
  <material name="DarkGrey">
    <color rgba="0.1 0.1 0.1 1.0"/>
  </material>
  <material name="Red">
    <color rgba="0.8 0.0 0.0 1.0"/>
  </material>
  <material name="White">
    <color rgba="1.0 1.0 1.0 1.0"/>
  </material>
  <material name="Yellow">
    <color rgba="0.96 0.88 0.14 1.0"/>
  </material>
  

  <!-- Base -->
  <link name="base_link">
    <!--inertial>
      <origin rpy="0 0 0" xyz="-0.00000106 0.00000109 0.0000387"/>
      <mass value="28.26649"/>
      <inertia ixx="0.465408937" ixy="0.002160024" ixz="-0.001760255" iyy="0.483193291" iyz="-0.000655952" izz="0.550939703"/>
    </inertial-->
    <visual>
      <origin rpy="0 0 0" xyz="0 0 0"/>
      <geometry>
        <mesh filename="file:///$(find kautham)/demos/models/robots/tiago/tiago/meshes/base/base_collision.dae"/>
      </geometry>
      <material name="White"/>
    </visual>
    <collision>
      <origin rpy="0 0 0" xyz="0 0 0"/>
      <geometry>
        <mesh filename="file:///$(find kautham)/demos/models/robots/tiago/tiago/meshes/base/base_collision.dae"/>
      </geometry>
      <material name="White"/>
    </collision>
  </link>
   
  <link name="wheel_right_link">
    <inertial>
      <origin rpy="0 0 0" xyz="0 0 -0.00207"/>
      <mass value="1.82362"/>
      <inertia ixx="0.00499743171" ixy="4.464e-08" ixz="-0.00000002245" iyy="0.00499741733" iyz="-1.64e-09" izz="0.00839239692"/>
    </inertial>
    <visual>
      <origin rpy="-0.0 0 0" xyz="0 0 0"/>
      <geometry>
          <!--mesh filename="package://pmb2_description/meshes/wheels/wheel.stl"/-->
        <cylinder length="0.04" radius="0.0985"/>
      </geometry>
      <material name="DarkGrey"/>
    </visual>
    <collision>
      <origin rpy="0 0 0" xyz="0 0 0"/>
      <geometry>
        <cylinder length="0.04" radius="0.0985"/>
      </geometry>
    </collision>
  </link>
  <joint name="wheel_right_joint" type="fixed">
    <parent link="base_link"/>
    <child link="wheel_right_link"/>
    <origin rpy="-1.57 0 0" xyz="0 -0.2022 0"/>
    <axis xyz="0 0 1"/>
    <limit effort="6.0" lower="-3.14" upper="3.14" velocity="10"/>
  </joint>
 
  <link name="wheel_left_link">
    <inertial>
      <origin rpy="0 0 0" xyz="0 0 0.00207"/>
      <mass value="1.82362"/>
      <inertia ixx="0.00499743171" ixy="-4.464e-08" ixz="-0.00000002245" iyy="0.00499741733" iyz="1.64e-09" izz="0.00839239692"/>
    </inertial>
    <visual>
      <origin rpy="-3.141592653589793 0 0" xyz="0 0 0"/>
      <geometry>
        <!--mesh filename="package://pmb2_description/meshes/wheels/wheel.stl"/-->
        <cylinder length="0.04" radius="0.0985"/>
      </geometry>
      <material name="DarkGrey"/>
    </visual>
    <collision>
      <origin rpy="0 0 0" xyz="0 0 0"/>
      <geometry>
        <cylinder length="0.04" radius="0.0985"/>
      </geometry>
    </collision>
  </link> 
  <joint name="wheel_left_joint" type="fixed">
    <parent link="base_link"/>
    <child link="wheel_left_link"/>
    <origin rpy="-1.57 0 0" xyz="0 0.2022 0"/>
    <axis xyz="0 0 1"/>
    <limit effort="6.0" lower="-3.14" upper="3.14" velocity="10"/>
  </joint>
 
 
  <!-- Bottom fixed part of column -->
  <link name="torso_fixed_link">
    <inertial>
      <origin rpy="0.00000 0.00000 0.00000" xyz="0.02435 -0.00464 0.15900"/>
      <mass value="14.01360"/>
      <inertia ixx="0.38341100000" ixy="0.00036400000" ixz="-0.02438900000" iyy="0.40577300000" iyz="-0.00078200000" izz="0.07699800000"/>
    </inertial>
    <visual>
      <origin rpy="0 0 0" xyz="0 0 0"/>
      <!--geometry>
        <mesh filename="file:///$(find kautham)/demos/models/robots/tiago/meshes/torso/torso_fix.dae" scale="1 1 1"/>
      </geometry-->
      <origin xyz="0.085 0.0 0.02"/>
      <geometry>
        <box size="0.4 0.25 0.04"/>
      </geometry>
      <material name="LightGrey"/>
    </visual>
    <collision>
      <origin rpy="0 0 0" xyz="0.085 0.0 0.02"/>
      <geometry>
        <box size="0.4 0.25 0.04"/>
      </geometry>
    </collision>
    <collision>
      <origin rpy="0 0 0" xyz="0 0 0.05"/>
      <geometry>
        <box size="0.25 0.25 0.1"/>
      </geometry>
    </collision>
  </link>
  <joint name="torso_fixed_joint" type="fixed">
    <origin rpy="0 0 0" xyz="-0.062 0.0 0.193"/>
    <parent link="base_link"/>
    <child link="torso_fixed_link"/>
  </joint>
  
  <!-- Middle extending  -->
  <!--link name="torso_fixed_column_link">
    <inertial>
      <origin rpy="0 0 0" xyz="0 0 0"/>
      <mass value="0.01"/>
      <inertia ixx="0.000001" ixy="0" ixz="0" iyy="0.000001" iyz="0" izz="0.000001"/>
    </inertial>
    <visual>
      <origin rpy="0 0 0" xyz="0 0 0.275"/>
      <geometry>
        <box size="0.18 0.2 0.55"/>
      </geometry>
      <material name="DarkGrey"/>
    </visual>
    <collision>
      <origin rpy="0 0 0" xyz="0 0 0.275"/>
      <geometry>
        <box size="0.23 0.23 0.55"/>
      </geometry>
      <material name="DarkGrey"/>
    </collision>
  </link>
  <joint name="torso_fixed_column_joint" type="fixed">
    <origin rpy="0 0 0" xyz="-0.062 0 0.195"/>
    <parent link="base_link"/>
    <child link="torso_fixed_column_link"/>
    <axis xyz="0 0 0"/>
  </joint-->
  
  <link name="torso_lift_link">
    <inertial>
      <origin rpy="0.00000 0.00000 0.00000" xyz="0.04361 -0.00116 -0.17334"/>
      <mass value="6.93198"/>
      <inertia ixx="0.24487000000" ixy="-0.00145600000" ixz="-0.00974200000" iyy="0.24926900000" iyz="0.00828100000" izz="0.09039500000"/>
    </inertial>
    <!-- Lifting body -->
    <visual>
      <origin rpy="0 0 0" xyz="0 0 0"/>
      <geometry>
        <!--mesh filename="package://tiago_description/meshes/torso/torso_lift_with_arm.stl" scale="1 1 1"/-->
        <mesh filename="file:///$(find kautham)/demos/models/robots/tiago/tiago/meshes/torso/torso_lift_collision.dae" scale="1 1 1"/>
      </geometry>
      <material name="White"/>
    </visual>
    <collision>
      <origin rpy="0 0 0" xyz="0 0 0"/>
      <geometry>
        <!--mesh filename="package://tiago_description/meshes/torso/torso_lift_collision_core.dae" scale="1 1 1"/-->
        <mesh filename="file:///$(find kautham)/demos/models/robots/tiago/tiago/meshes/torso/torso_lift_collision.dae" scale="1 1 1"/>
      </geometry>
      <material name="LightGrey"/>
    </collision>
    <!--collision>
      <origin rpy="0 0 0" xyz="0 0 0"/>
      <geometry>
        <mesh filename="package://tiago_description/meshes/torso/torso_lift_collision_shoulder.dae" scale="1 1 1"/>
      </geometry>
      <material name="LightGrey"/>
    </collision>
    <collision>
      <origin rpy="0 0 0" xyz="0 0 0"/>
      <geometry>
        <mesh filename="package://tiago_description/meshes/torso/torso_lift_collision_neck.dae" scale="1 1 1"/>
      </geometry>
      <material name="LightGrey"/>
    </collision-->
  </link>
  <joint name="torso_lift_joint" type="prismatic">
    <origin rpy="0.0 0.0 0.0" xyz="0.0 0.0 0.597"/>
    <parent link="torso_fixed_link"/>
    <child link="torso_lift_link"/>
    <axis xyz="0 0 1"/>
    <limit effort="2000" lower="0" upper="0.35" velocity="0.07"/>
    <calibration rising="0.0"/>
    <dynamics damping="1000"/>
    <safety_controller k_position="20" k_velocity="20" soft_lower_limit="0.0" soft_upper_limit="0.35"/>
  </joint>

  
  <link name="head_1_link">
    <inertial>
      <origin rpy="0.00000 0.00000 0.00000" xyz="-0.00508 0.00237 0.07229"/>
      <mass value="0.62220"/>
      <inertia ixx="0.00119200000" ixy="-0.00000700000" ixz="0.00009600000" iyy="0.00140200000" iyz="0.00000400000" izz="0.00088900000"/>
    </inertial>
    <visual>
      <origin rpy="0 0 0" xyz="0 0 0"/>
      <geometry>
        <!--mesh filename="package://tiago_description/meshes/head/head_1.stl" scale="1 1 1"/-->
        <mesh filename="file:///$(find kautham)/demos/models/robots/tiago/tiago/meshes/head/head_1_collision.dae" scale="1 1 1"/>
      </geometry>
      <material name="White"/>
    </visual>
    <collision>
      <origin rpy="0 0 0.0" xyz="0.0 0 0"/>
      <geometry>
        <!--mesh filename="package://tiago_description/meshes/head/head_1_collision.dae" scale="1 1 1"/-->
        <mesh filename="file:///$(find kautham)/demos/models/robots/tiago/tiago/meshes/head/head_1_collision.dae" scale="1 1 1"/>
      </geometry>
      <material name="White"/>
    </collision>
  </link>
  <joint name="head_1_joint" type="revolute">
    <parent link="torso_lift_link"/>
    <child link="head_1_link"/>
    <origin rpy="0 0 0" xyz="0.182 0.0 0.0"/>
    <axis xyz="0 0 1"/>
    <limit effort="5.197" lower="-1.3089969389957472" upper="1.3089969389957472" velocity="3.0"/>
    <dynamics damping="0.5" friction="1.0"/>
    <safety_controller k_position="20" k_velocity="20" soft_lower_limit="-1.2389969389957471" soft_upper_limit="1.2389969389957471"/>
  </joint>
  
  <link name="head_2_link">
    <inertial>
      <origin rpy="0.00000 0.00000 0.00000" xyz="0.04700 0.05542 0.00022"/>
      <mass value="0.66123"/>
      <inertia ixx="0.00462000000" ixy="0.00068900000" ixz="0.00000600000" iyy="0.00486100000" iyz="0.00000600000" izz="0.00313200000"/>
    </inertial>
    <visual>
      <origin rpy="0 0 0" xyz="0 0 0"/>
      <geometry>
        <!--mesh filename="package://tiago_description/meshes/head/head_2.stl" scale="1 1 1"/-->
        <mesh filename="file:///$(find kautham)/demos/models/robots/tiago/tiago/meshes/head/head_2_collision.dae" scale="1 1 1"/>
      </geometry>
      <material name="White"/>
    </visual>
    <collision>
      <origin rpy="0 0 0" xyz="0 0 0"/>
      <geometry>
        <!--mesh filename="package://tiago_description/meshes/head/head_2_collision.dae" scale="1 1 1"/-->
        <mesh filename="file:///$(find kautham)/demos/models/robots/tiago/tiago/meshes/head/head_2_collision.dae" scale="1 1 1"/>
      </geometry>
    </collision>
  </link>
  <joint name="head_2_joint" type="revolute">
    <parent link="head_1_link"/>
    <child link="head_2_link"/>
    <origin rpy="1.5707963267948966 0 0" xyz="0.005 0.0 0.098"/>
    <axis xyz="0 0 1"/>
    <limit effort="2.77" lower="-1.0471975511965976" upper="0.7853981633974483" velocity="3.0"/>
    <dynamics damping="0.5" friction="1.0"/>
    <safety_controller k_position="20" k_velocity="20" soft_lower_limit="-0.9771975511965976" soft_upper_limit="0.7853981633974483"/>
  </joint>
  
  <!--************************-->
  <!--        SHOULDER        -->
  <!--************************-->
  <link name="arm_1_link">
    <inertial>
      <!--<origin xyz="0.061191 ${reflect * -0.022397} -0.012835" rpy="0.00000 0.00000 0.00000"/>-->
      <origin rpy="0.00000 0.00000 0.00000" xyz="0.061191 -0.022397 -0.012835"/>
      <mass value="1.563428"/>
      <inertia ixx="0.002471" ixy="-0.001809" ixz="-0.001202" iyy="0.006132" iyz="0.000494" izz="0.006704"/>
    </inertial>
    <!-- M90 module -->
    <visual>
      <origin rpy="0 0 0" xyz="0 0 0"/>
      <geometry>
        <!--mesh filename="package://tiago_description/meshes/arm/arm_1.stl" scale="1 1 1"/-->
        <mesh filename="file:///$(find kautham)/demos/models/robots/tiago/tiago/meshes/arm/arm_1_collision.dae" scale="1 1 1"/>
      </geometry>
      <material name="White"/>
    </visual>
    <collision>
      <origin rpy="0 0 0" xyz="0 0 0"/>
      <geometry>
        <!--mesh filename="package://tiago_description/meshes/arm/arm_1_collision.dae" scale="1 1 1"/-->
        <mesh filename="file:///$(find kautham)/demos/models/robots/tiago/tiago/meshes/arm/arm_1_collision.dae" scale="1 1 1"/>
      </geometry>
    </collision>
  </link>
  <joint name="arm_1_joint" type="revolute">
    <parent link="torso_lift_link"/>
    <child link="arm_1_link"/>
    <origin rpy="0 0 -1.5707963267948966" xyz="0.15505 0.014 -0.151"/>
    <axis xyz="0 0 1"/>
    <limit effort="43.0" lower="0.0" upper="2.748893571891069" velocity="1.95"/>
    <dynamics damping="1.0" friction="1.0"/>
    <safety_controller k_position="20" k_velocity="20" soft_lower_limit="0.07" soft_upper_limit="2.678893571891069"/>
  </joint>
  
  <link name="arm_2_link">
    <inertial>
      <origin rpy="0.00000 0.00000 0.00000" xyz="0.030432 0.000229 -0.005942"/>
      <mass value="1.800397"/>
      <inertia ixx="0.001809" ixy="1.5e-05" ixz="0.000254" iyy="0.004333" iyz="1.4e-05" izz="0.004341"/>
    </inertial>
    <visual>
      <!-- <origin xyz="0 0 0" rpy="${180 * deg_to_rad} ${0 * deg_to_rad} ${-90 * deg_to_rad}" /> -->
      <origin rpy="0.0 0.0 0.0" xyz="0 0 0"/>
      <geometry>
        <!--mesh filename="package://tiago_description/meshes/arm/arm_2.stl" scale="1 1 1"/-->
        <mesh filename="file:///$(find kautham)/demos/models/robots/tiago/tiago/meshes/arm/arm_2_collision.dae" scale="1 1 1"/>
      </geometry>
      <material name="DarkGrey"/>
    </visual>
    <collision>
      <!-- <origin xyz="0 0 0" rpy="${180 * deg_to_rad} ${0 * deg_to_rad} ${-90 * deg_to_rad}" /> -->
      <origin rpy="0.0 0.0 0.0" xyz="0 0 0"/>
      <geometry>
        <!--mesh filename="package://tiago_description/meshes/arm/arm_2_collision.dae" scale="1 1 1"/-->
        <mesh filename="file:///$(find kautham)/demos/models/robots/tiago/tiago/meshes/arm/arm_2_collision.dae" scale="1 1 1"/>
      </geometry>
    </collision>
  </link>
  <joint name="arm_2_joint" type="revolute">
    <parent link="arm_1_link"/>
    <child link="arm_2_link"/>
    <origin rpy="1.5707963267948966 0.0 0.0" xyz="0.125 0.0195 -0.031"/>
    <axis xyz="0 0 1"/>
    <limit effort="43.0" lower="-1.5707963267948966" upper="1.090830782496456" velocity="1.95"/>
    <dynamics damping="1.0" friction="1.0"/>
    <safety_controller k_position="20" k_velocity="20" soft_lower_limit="-1.5007963267948965" soft_upper_limit="1.020830782496456"/>
  </joint>
  
  <link name="arm_3_link">
    <inertial>
      <origin rpy="0.00000 0.00000 0.00000" xyz="0.007418 -0.004361 -0.134194"/>
      <mass value="2.343502"/>
      <inertia ixx="0.019541" ixy="-0.000105" ixz="-0.001717" iyy="0.019936" iyz="0.000852" izz="0.002864"/>
    </inertial>
    <visual>
      <origin rpy="0 0 0" xyz="0 0 0"/>
      <geometry>
        <!--mesh filename="package://tiago_description/meshes/arm/arm_3.stl" scale="1 1 1"/-->
        <mesh filename="file:///$(find kautham)/demos/models/robots/tiago/tiago/meshes/arm/arm_3_collision.dae" scale="1 1 1"/>
      </geometry>
      <material name="DarkGrey"/>
    </visual>
    <collision>
      <origin rpy="0 0 0" xyz="0 0 0"/>
      <geometry>
        <!--mesh filename="package://tiago_description/meshes/arm/arm_3_collision.dae" scale="1 1 1"/-->
        <mesh filename="file:///$(find kautham)/demos/models/robots/tiago/tiago/meshes/arm/arm_3_collision.dae" scale="1 1 1"/>
      </geometry>
    </collision>
  </link>
  <joint name="arm_3_joint" type="revolute">
    <parent link="arm_2_link"/>
    <child link="arm_3_link"/>
    <origin rpy="-1.5707963267948966 0.0 1.5707963267948966" xyz="0.0895 0.0 -0.0015"/>
    <axis xyz="0 0 1"/>
    <limit effort="26" lower="-3.5342917352885173" upper="1.5707963267948966" velocity="2.35"/>
    <dynamics damping="1.0" friction="1.0"/>
    <safety_controller k_position="20" k_velocity="20" soft_lower_limit="-3.4642917352885174" soft_upper_limit="1.5007963267948965"/>
  </joint>
  
  <!--************************-->
  <!--        ELBOW           -->
  <!--************************-->
  <link name="arm_4_link">
    <inertial>
      <origin rpy="0.00000 0.00000 0.00000" xyz="-0.095658 0.014666 0.018133"/>
      <mass value="1.432697"/>
      <inertia ixx="0.002040" ixy="0.000725" ixz="-0.00115" iyy="0.008424" iyz="-0.000204" izz="0.008686"/>
    </inertial>
    <visual>
      <origin rpy="0 0 0" xyz="0 0 0"/>
      <geometry>
        <!--mesh filename="package://tiago_description/meshes/arm/arm_4.stl" scale="1 1 1"/-->
        <mesh filename="file:///$(find kautham)/demos/models/robots/tiago/tiago/meshes/arm/arm_4_collision.dae" scale="1 1 1"/>
      </geometry>
      <material name="DarkGrey"/>
    </visual>
    <collision>
      <origin rpy="0 0 0" xyz="0 0 0"/>
      <geometry>
        <!--mesh filename="package://tiago_description/meshes/arm/arm_4_collision.dae" scale="1 1 1"/-->
        <mesh filename="file:///$(find kautham)/demos/models/robots/tiago/tiago/meshes/arm/arm_4_collision.dae" scale="1 1 1"/>
      </geometry>
    </collision>
  </link>
  <joint name="arm_4_joint" type="revolute">
    <parent link="arm_3_link"/>
    <child link="arm_4_link"/>
    <origin rpy="-1.5707963267948966 -1.5707963267948966 0.0" xyz="-0.02 -0.027 -0.222"/>
    <axis xyz="0 0 1"/>
    <limit effort="26" lower="-0.39269908169872414" upper="2.356194490192345" velocity="2.35"/>
    <dynamics damping="1.0" friction="1.0"/>
    <safety_controller k_position="20" k_velocity="20" soft_lower_limit="-0.32269908169872413" soft_upper_limit="2.286194490192345"/>
  </joint>
  
  <!--************************-->
  <!--        WRIST           -->
  <!--************************-->
  <link name="arm_5_link">
    <inertial>
      <origin rpy="0.00000 0.00000 0.00000" xyz="0.001078 -0.000151 -0.077173"/>
      <mass value="1.655819"/>
      <inertia ixx="0.00613800000" ixy="-0.00000400000" ixz="0.00015600000" iyy="0.00564000000" iyz="0.00002200000" izz="0.00179700000"/>
    </inertial>
    <visual>
      <origin rpy="0 0 0" xyz="0 0 0"/>
      <geometry>
        <!--mesh filename="package://tiago_description/meshes/arm/arm_5-wrist-2010.stl" scale="1 1 1"/-->
        <mesh filename="file:///$(find kautham)/demos/models/robots/tiago/tiago/meshes/arm/arm_5_collision.dae" scale="1 1 1"/>
      </geometry>
      <material name="LightGrey"/>
    </visual>
    <collision>
      <origin rpy="0 0 0" xyz="0 0 0"/>
      <geometry>
        <!--mesh filename="package://tiago_description/meshes/arm/arm_5_collision-wrist-2010.dae" scale="1 1 1"/-->
        <mesh filename="file:///$(find kautham)/demos/models/robots/tiago/tiago/meshes/arm/arm_5_collision.dae" scale="1 1 1"/>
      </geometry>
    </collision>
  </link>
  <joint name="arm_5_joint" type="revolute">
    <parent link="arm_4_link"/>
    <child link="arm_5_link"/>
    <origin rpy="1.5707963267948966 -1.5707963267948966 -1.5707963267948966" xyz="-0.162 0.02 0.027"/>
    <axis xyz="0 0 1"/>
    <limit effort="3" lower="-2.0943951023931953" upper="2.0943951023931953" velocity="1.95"/>
    <dynamics damping="1.0" friction="1.0"/>
    <safety_controller k_position="20" k_velocity="20" soft_lower_limit="-2.0743951023931952" soft_upper_limit="2.0743951023931952"/>
  </joint>
  
  <link name="arm_6_link">
    <inertial>
      <origin rpy="0.00000 0.00000 0.00000" xyz="-0.000153 -0.003122 0.000183"/>
      <mass value="0.370063"/>
      <inertia ixx="0.00021500000" ixy="0.00000000000" ixz="0.00000000000" iyy="0.00017000000" iyz="0.00000200000" izz="0.00017400000"/>
    </inertial>
    <visual>
      <origin rpy="0 0 0" xyz="0 0 0"/>
      <geometry>
        <!--mesh filename="package://tiago_description/meshes/arm/arm_6-wrist-2010.stl" scale="1 1 1"/-->
        <mesh filename="file:///$(find kautham)/demos/models/robots/tiago/tiago/meshes/arm/arm_6_collision.dae" scale="1 1 1"/>
      </geometry>
      <material name="LightGrey"/>
    </visual>
    <collision>
      <origin rpy="0 0 0" xyz="0 0 0"/>
      <geometry>
        <!--mesh filename="package://tiago_description/meshes/arm/arm_6_collision-wrist-2010.dae" scale="1 1 1"/-->
        <mesh filename="file:///$(find kautham)/demos/models/robots/tiago/tiago/meshes/arm/arm_6_collision.dae" scale="1 1 1"/>
      </geometry>
    </collision>
  </link>
  <joint name="arm_6_joint" type="revolute">
    <parent link="arm_5_link"/>
    <child link="arm_6_link"/>
    <origin rpy="0.0 -1.5707963267948966 -1.5707963267948966" xyz="0 0 0.15"/>
    <axis xyz="0 0 1"/>
    <limit effort="6.6" lower="-1.413716694115407" upper="1.413716694115407" velocity="1.76"/>
    <dynamics damping="1.0" friction="1.0"/>
    <safety_controller k_position="20" k_velocity="20" soft_lower_limit="-1.3937166941154069" soft_upper_limit="1.3937166941154069"/>
  </joint>
  <link name="arm_7_link">
    <inertial>
      <origin rpy="0.00000 0.00000 0.00000" xyz="0.000010 -0.000003 -0.007774"/>
      <mass value="0.234252"/>
      <inertia ixx="0.00014200000" ixy="0.00000000000" ixz="0.00000000000" iyy="0.00011300000" iyz="0.00000000000" izz="0.00005200000"/>
    </inertial>
    <visual>
      <origin rpy="0 0 0" xyz="0 0 0"/>
      <geometry>
        <cylinder length="0.005" radius="0.005"/>
      </geometry>
      <material name="LightGrey"/>
    </visual>
    <collision>
      <origin rpy="0 0 0" xyz="0 0 0"/>
      <geometry>
        <cylinder length="0.005" radius="0.005"/>
      </geometry>
    </collision>
  </link>
  <joint name="arm_7_joint" type="revolute">
    <parent link="arm_6_link"/>
    <child link="arm_7_link"/>
    <origin rpy="1.57079632679 0.0 1.57079632679" xyz="0.066 0 0"/> <!--The 0.066 was 0 , when exported from tiago_description xacro file ¿?-->
    <axis xyz="0 0 1"/>
    <limit effort="6.6" lower="-2.0943951023931953" upper="2.0943951023931953" velocity="1.76"/>
    <dynamics damping="1.0" friction="1.0"/>
    <safety_controller k_position="20" k_velocity="20" soft_lower_limit="-2.0743951023931952" soft_upper_limit="2.0743951023931952"/>
  </joint>

  
  <!-- reflect: Set to 1 for a right arm, or to -1 for a left arm-->
<!--
  <xacro:if value="${wrist_model == 'wrist-2010'}">
    <xacro:property name="tool_link_z_offset"           value="0.046"/>
  </xacro:if>
  <xacro:if value="${wrist_model == 'wrist-2017'}">
   <xacro:property name="tool_link_z_offset"           value="${ 0.046 if has_ft_sensor else 0.0573 }"/>
  </xacro:if>
  <joint name="${name}_tool_joint" type="fixed">
    <parent link="${name}_7_link" />
    <child link="${name}_tool_link" />
      <origin xyz="0 0 ${reflect * tool_link_z_offset}" rpy="${90.0 * deg_to_rad} ${reflect * -90.0 * deg_to_rad} ${180 * deg_to_rad}" />
  </joint>
-->
  <link name="arm_tool_link">
    <inertial>
      <mass value="0.1" />
      <inertia ixx="0.0" ixy="0.0" ixz="0.0" iyy="0.0" iyz="0.0" izz="0.0" />
    </inertial>
    <visual>
      <origin xyz="0.001 0 0" rpy="0 1.57079632679 0" />
      <geometry>
        <cylinder radius="0.005" length="0.005"/>
      </geometry>
      <material name="LightGrey" />
    </visual>
    <collision>
      <origin xyz="0.001 0 0" rpy="0 1.57079632679 0" />
      <geometry>
        <cylinder radius="0.005" length="0.005"/>
      </geometry>
    </collision>
  </link>
  <joint name="arm_tool_joint" type="fixed">
     <parent link="arm_7_link" />
     <child link="arm_tool_link" />
        <!--origin xyz="0 0 -0.046" rpy="1.57079632679 1.57079632679 3.1415" /--><!--LEFT-->
        <origin xyz="0 0 0.046" rpy="1.57079632679 -1.57079632679 3.1415" /><!--RIGHT-->
   </joint>
  
  
  <!--***********************-->
  <!--        TOOL           -->
  <!--***********************-->

  <joint name="gripper_joint" type="fixed">
      <parent link="arm_7_link"/>
      <child link="gripper_link"/>
      <origin rpy="3.14 0 1.57" xyz="0 0 0.001"/>
  </joint>


  <link name="gripper_link">
    <inertial>
      <origin rpy="0.0 0.0 0.0" xyz="-0.000294 0.000291 -0.033086"/>
      <mass value="0.001"/>
      <inertia ixx="0.000693" ixy="0.000045" ixz="-0.000000" iyy="0.001024" iyz="0.000000" izz="0.000672"/>
    </inertial>
    <visual>
      <origin rpy="0 0 0" xyz="0 0 0"/>
      <geometry>
        <mesh filename="file:///$(find kautham)/demos/models/robots/tiago/tiago/meshes/gripper/gripper_link.dae"/>
      </geometry>
      <material name="White"/>
    </visual>
    <collision>
      <origin rpy="0 0 0" xyz="0 0 0"/>
      <geometry>
        <mesh filename="file:///$(find kautham)/demos/models/robots/tiago/tiago/meshes/gripper/gripper_link_collision.dae"/>
      </geometry>
    </collision>
  </link>

  <link name="gripper_right_finger_link">
    <inertial>
      <origin rpy="0 0 0" xyz="-0.004470 0.010766 -0.121013"/>
      <mass value="0.00109980"/>
      <inertia ixx="0.000232" ixy="-0.000005" ixz="-0.000032" iyy="0.000224" iyz="0.000036" izz="0.000029"/>
    </inertial>
    <visual>
      <origin rpy="0 0 3.1415" xyz="0 0 0"/>
      <geometry>
        <mesh filename="file:///$(find kautham)/demos/models/robots/tiago/tiago/meshes/gripper/gripper_finger_link.dae" scale="-1 -1 1"/>
      </geometry>
      <material name="White"/>
    </visual>
    <collision>
      <origin rpy="0 0 3.1415" xyz="0.005 0 -0.165"/>
      <geometry>
        <box size="0.01 0.05 0.11"/>
      </geometry>
    </collision>
  </link>

  <joint name="gripper_right_finger_joint" type="prismatic">
    <origin rpy="0 0 0" xyz="0. 0 0"/>
    <parent link="gripper_link"/>
    <child link="gripper_right_finger_link"/>
    <axis xyz="1 0 0"/>
    <limit effort="16" lower="0.0" upper="0.045" velocity="0.05"/>
    <calibration rising="0.0"/>
    <dynamics damping="80"/>
    <safety_controller k_position="20" k_velocity="20" soft_lower_limit="0.001" soft_upper_limit="0.044"/>
  </joint>
  <link name="gripper_left_finger_link">
    <inertial>
      <origin rpy="0 0 0" xyz="-0.004470 0.010766 -0.121013"/>
      <mass value="0.00109980"/>
      <inertia ixx="0.000232" ixy="-0.000005" ixz="-0.000032" iyy="0.000224" iyz="0.000036" izz="0.000029"/>
    </inertial>
    <visual>
      <origin rpy="0 0 3.1415" xyz="0 0 0"/>
      <geometry>
        <mesh filename="file:///$(find kautham)/demos/models/robots/tiago/tiago/meshes/gripper/gripper_finger_link.dae"/>
      </geometry>
      <material name="White"/>
    </visual>
    <collision>
      <origin rpy="0 0 3.1415" xyz="-0.005 0 -0.165"/>
      <geometry>
        <box size="0.01 0.05 0.11"/>
      </geometry>
    </collision>
  </link>

  <joint name="gripper_left_finger_joint" type="prismatic">
    <origin rpy="0 0 0" xyz="0. 0 0"/>
    <parent link="gripper_link"/>
    <child link="gripper_left_finger_link"/>
    <axis xyz="-1 0 0"/>
    <limit effort="16" lower="0" upper="0.045" velocity="0.05"/>
    <calibration rising="0.0"/>
    <dynamics damping="80"/>
    <safety_controller k_position="20" k_velocity="20" soft_lower_limit="0.001" soft_upper_limit="0.044"/>
  </joint>
  
  
</robot>

