<?xml version="1.0" ?>

<robot name="ur5">

    <link name="base_link">
        <visual>
            <origin xyz="0 0 0" rpy="0 0 3.14159"/>
            <geometry>
                <mesh filename="../UR5/visual/base.dae"/>
            </geometry>
        </visual>
        <collision>
            <origin xyz="0 0 0" rpy="0 0 3.14159"/>
            <geometry>
                <mesh filename="../UR5/collision/base.stl"/>
            </geometry>
        </collision>
        <inertial>
            <mass value="4.0000"/>
            <inertia ixx="0.00443333156" ixy="0" ixz="0" iyy="0.00443333156" iyz="0" izz="0.0072"/>
        </inertial>
    </link>
    
    <joint name="shoulder_pan_joint" type="revolute">
        <parent link="base_link"/>
        <child link="shoulder_link"/>
        <origin xyz="0 0 0.089159" rpy="0 0 0"/>
        <axis xyz="0 0 1"/>
        <limit effort="150" lower="-6.2831853" upper="6.2831853" velocity="3.14159"/>
    </joint>
    
    <link name="shoulder_link">
        <visual>
            <origin xyz="0 0 0" rpy="0 0 3.14159"/>
            <geometry>
                <mesh filename="../UR5/visual/shoulder.dae"/>
            </geometry>
        </visual>
        <collision>
            <origin xyz="0 0 0" rpy="0 0 3.14159"/>
            <geometry>
                <mesh filename="../UR5/collision/shoulder.stl"/>
            </geometry>
        </collision>
        <inertial>
            <mass value="3.7000"/>
            <inertia ixx="0.010267495893" ixy="0" ixz="0" iyy="0.010267495893" iyz="0" izz="0.00666"/>
        </inertial>
    </link>
    
    <joint name="shoulder_lift_joint" type="revolute">
        <parent link="shoulder_link"/>
        <child link="upper_arm_link"/>
        <origin xyz="0 0 0" rpy="1.570796327 0 0"/>
        <axis xyz="0 0 1"/>
        <limit effort="150" lower="-6.2831853" upper="6.2831853" velocity="3.14159"/>
    </joint>
    
    <link name="upper_arm_link">
        <visual>
            <origin xyz="0 0 0.13585" rpy="1.57079 0 -1.57079"/>
            <geometry>
                <mesh filename="../UR5/visual/upperarm.dae"/>
            </geometry>
        </visual>
        <collision>
            <origin xyz="0 0 0.13585" rpy="1.57079 0 -1.57079"/>
            <geometry>
                <mesh filename="../UR5/collision/upperarm.stl"/>
            </geometry>
        </collision>
        <inertial>
          <mass value="8.3930"/>
          <origin xyz="0 0 0.28"/>
          <inertia ixx="0.22689067591" ixy="0" ixz="0" iyy="0.22689067591" iyz="0" izz="0.0151074"/>
        </inertial>
    </link>
    
    <joint name="elbow_joint" type="revolute">
        <parent link="upper_arm_link"/>
        <child link="fore_arm_link"/>
        <origin xyz="-0.425 0 0" rpy="0 0 0"/>
        <axis xyz="0 0 1"/>
        <limit effort="150" lower="-6.2831853" upper="6.2831853" velocity="3.14159"/>
        <!-- <limit effort="150" lower="-3.14159" upper="3.14159" velocity="3.14159"/> -->
    </joint>
    
    <link name="fore_arm_link">
        <visual>
            <origin xyz="0 0 0.0165" rpy="1.57079 0 -1.57079"/>
            <geometry>
                <mesh filename="../UR5/visual/forearm.dae"/>
            </geometry>
        </visual>
        <collision>
            <origin xyz="0 0 0.0165" rpy="1.57079 0 -1.57079"/>
            <geometry>
                <mesh filename="../UR5/collision/forearm.stl"/>
            </geometry>
        </collision>
        <inertial>
            <mass value="2.3300"/>
            <origin xyz="0 0 0.25"/>
            <inertia ixx="0.049443313556" ixy="0" ixz="0" iyy="0.049443313556" iyz="0" izz="0.004095"/>
        </inertial>
    </link>
    
    <joint name="wrist_1_joint" type="revolute">
        <parent link="fore_arm_link"/>
        <child link="wrist_1_link"/>
        <origin xyz="-0.39225 0 0.10915" rpy="0 0 0"/>
        <axis xyz="0 0 1"/>
        <limit effort="28" lower="-6.2831853" upper="6.2831853" velocity="3.14159"/>
      </joint>
    
    <link name="wrist_1_link">
        <visual>
            <origin xyz="0 0 -0.093" rpy="1.57079 0 0"/>
            <geometry>
                <mesh filename="../UR5/visual/wrist1.dae"/>
            </geometry>
        </visual>
        <collision>
            <origin xyz="0 0 -0.093" rpy="1.57079 0 0"/>
            <geometry>
                <mesh filename="../UR5/collision/wrist1.stl"/>
            </geometry>
        </collision>
        <inertial>
            <mass value="1.2190"/>
            <inertia ixx="0.111172755531" ixy="0" ixz="0" iyy="0.111172755531" iyz="0" izz="0.21942"/>
        </inertial>
    </link>
    
    <joint name="wrist_2_joint" type="revolute">
        <parent link="wrist_1_link"/>
        <child link="wrist_2_link"/>
        <origin xyz="0 -0.09465 -1.941303950897609e-11" rpy="1.570796327 0 0"/>
        <axis xyz="0 0 1"/>
        <limit effort="28" lower="-6.2831853" upper="6.2831853" velocity="3.14159"/>
    </joint>
    
    <link name="wrist_2_link">
        <visual>
            <origin xyz="0 0 -0.095" rpy="0 0 0"/>
            <geometry>
                <mesh filename="../UR5/visual/wrist2.dae"/>
            </geometry>
        </visual>
        <collision>
            <origin xyz="0 0 -0.095" rpy="0 0 0"/>
            <geometry>
                <mesh filename="../UR5/collision/wrist2.stl"/>
            </geometry>
        </collision>
        <inertial>
            <mass value="1.2190"/>
            <inertia ixx="0.111172755531" ixy="0" ixz="0" iyy="0.111172755531" iyz="0" izz="0.21942"/>
        </inertial>
    </link>
    
    <joint name="wrist_3_joint" type="revolute">
        <parent link="wrist_2_link"/>
        <child link="wrist_3_link"/>
        <origin xyz="0 0.0823 -1.688001216681175e-11" rpy="1.570796326589793 3.141592653589793 3.141592653589793"/>
        <axis xyz="0 0 1"/>
        <limit effort="28" lower="-6.2831853" upper="6.2831853" velocity="3.14159"/>
    </joint>
    
    <link name="wrist_3_link">
        <visual>
            <origin xyz="0 0 -0.0818" rpy="1.57079 0 0"/>
            <geometry>
                <mesh filename="../UR5/visual/wrist3.dae"/>
            </geometry>
        </visual>
        <collision>
            <origin xyz="0 0 -0.0818" rpy="1.57079 0 0"/>
            <geometry>
                <mesh filename="../UR5/collision/wrist3.stl"/>
            </geometry>
        </collision>
        <inertial>
            <mass value="0.1879"/>
            <inertia ixx="0.0171364731454" ixy="0" ixz="0" iyy="0.0171364731454" iyz="0" izz="0.033822"/>
        </inertial>
    </link>

</robot>
