<?xml version="1.0"?>
<robot name="madar">

    <!-- BEGIN: T-STRUCTURE -->
    <link name="madar_base_link">
        <visual>
            <geometry>
                <mesh filename="/meshes/estructura_asm.dae"/>
            </geometry>
        </visual>
        <collision>
            <origin xyz="0 0 0.375" rpy="0 0 0"/>
            <geometry>
                <cylinder radius="0.4" length="0.75"/>
            </geometry>
        </collision>
        <collision>
            <origin xyz="0 0 1.395" rpy="0 0 0"/>
            <geometry>
                <box size="0.5 0.08 0.05"/>
            </geometry>
        </collision>
        <collision>
            <origin xyz="0 0 1.056" rpy="0 0 0"/>
            <geometry>
                <box size="0.08 0.08 0.63"/>
            </geometry>
        </collision>
        <collision>
            <origin xyz="0 -0.14 0.916" rpy="0 0 0" />
            <geometry>
                <box size="0.43 0.2 0.33"/>
            </geometry>
        </collision>
    </link>
    <!-- END: T-STRUCTURE -->

    <!-- END: WHEELS -->
    <joint name="motor_1" type="continuous">
      <parent link="madar_base_link"/>
      <child link="wheel_1_link"/>
      <axis xyz="-1 0 0"/>
      <origin rpy="2.0944 0 1.5708" xyz="0 -0.2905 0.1"/>
    </joint>
  
    <link name="wheel_1_link">
      <visual>
        <geometry>
            <mesh filename="/meshes/wheel.dae"/>
        </geometry>
      </visual>
      <collision>
        <geometry>
          <sphere radius="0.10"/>
        </geometry>
      </collision>
      <inertial>
         <mass value="10"/>
         <inertia ixx="0.04" ixy="0" ixz="0" iyy="0.04" iyz="0" izz="0.04"/> <!-- Provisional inertia values -->
       </inertial>
    </link>
  
    <joint name="motor_2" type="continuous">
      <parent link="madar_base_link"/>
      <child link="wheel_2_link"/>
      <axis xyz="-1 0 0"/>
      <origin rpy="0 0 3.66519" xyz="0.25158 0.14525 0.1"/>
    </joint>
  
    <link name="wheel_2_link">
      <visual>
        <geometry>
            <mesh filename="/meshes/wheel.dae"/>
        </geometry>
      </visual>
      <collision>
        <geometry>
          <sphere radius="0.10"/>
        </geometry>
      </collision>
      <inertial>
         <mass value="10"/>
         <inertia ixx="0.04" ixy="0" ixz="0" iyy="0.04" iyz="0" izz="0.04"/>
       </inertial>
    </link>
  
    <joint name="motor_3" type="continuous">
      <parent link="madar_base_link"/>
      <child link="wheel_3_link"/>
      <axis xyz="-1 0 0"/>
      <origin rpy="0 0 5.75959" xyz="-0.25158 0.14525 0.1"/>
    </joint>
  
    <link name="wheel_3_link">
      <visual>
        <geometry>
            <mesh filename="/meshes/wheel.dae"/>
        </geometry>
      </visual>
      <collision>
        <geometry>
          <sphere radius="0.10"/>
        </geometry>
      </collision>
      <inertial>
         <mass value="10"/>
         <inertia ixx="0.04" ixy="0" ixz="0" iyy="0.04" iyz="0" izz="0.04"/>
       </inertial>
    </link>
  
    <!-- END: WHEELS -->

    <!-- BEGIN: ARM RIGHT -->

    <joint name="right_base_link" type="fixed">
        <parent link="madar_base_link"/>
        <child link="right_base_link"/>
        <origin xyz="0.256 0.0 1.389" rpy="3.142 -0.7874 0.000"/>
    </joint>

    <link name="right_base_link">
        <visual>
            <origin xyz="0 0 0" rpy="0 0 3.14159"/>
            <geometry>
                <mesh filename="../UR5/visual/base.dae"/>
            </geometry>
        </visual>
        <collision>
            <origin xyz="0 0 0" rpy="0 0 3.14159"/>
            <geometry>
                <mesh filename="../UR5/collision/base.stl"/>
            </geometry>
        </collision>
        <inertial>
            <mass value="4.0000"/>
            <inertia ixx="0.00443333156" ixy="0" ixz="0" iyy="0.00443333156" iyz="0" izz="0.0072"/>
        </inertial>
    </link>
    
    <joint name="right_shoulder_pan_joint" type="revolute">
        <parent link="right_base_link"/>
        <child link="right_shoulder_link"/>
        <origin xyz="0 0 0.089159" rpy="0 0 0"/>
        <axis xyz="0 0 1"/>
        <limit effort="150" lower="-6.2831853" upper="6.2831853" velocity="3.14159"/>
    </joint>
    
    <link name="right_shoulder_link">
        <visual>
            <origin xyz="0 0 0" rpy="0 0 3.14159"/>
            <geometry>
                <mesh filename="../UR5/visual/shoulder.dae"/>
            </geometry>
        </visual>
        <collision>
            <origin xyz="0 0 0" rpy="0 0 3.14159"/>
            <geometry>
                <mesh filename="../UR5/collision/shoulder.stl"/>
            </geometry>
        </collision>
        <inertial>
            <mass value="3.7000"/>
            <inertia ixx="0.010267495893" ixy="0" ixz="0" iyy="0.010267495893" iyz="0" izz="0.00666"/>
        </inertial>
    </link>
    
    <joint name="right_shoulder_lift_joint" type="revolute">
        <parent link="right_shoulder_link"/>
        <child link="right_upper_arm_link"/>
        <origin xyz="0 0 0" rpy="1.570796327 0 0"/>
        <axis xyz="0 0 1"/>
        <limit effort="150" lower="-6.2831853" upper="6.2831853" velocity="3.14159"/>
    </joint>
    
    <link name="right_upper_arm_link">
        <visual>
            <origin xyz="0 0 0.13585" rpy="1.57079 0 -1.57079"/>
            <geometry>
                <mesh filename="../UR5/visual/upperarm.dae"/>
            </geometry>
        </visual>
        <collision>
            <origin xyz="0 0 0.13585" rpy="1.57079 0 -1.57079"/>
            <geometry>
                <mesh filename="../UR5/collision/upperarm.stl"/>
            </geometry>
        </collision>
        <inertial>
          <mass value="8.3930"/>
          <origin xyz="0 0 0.28"/>
          <inertia ixx="0.22689067591" ixy="0" ixz="0" iyy="0.22689067591" iyz="0" izz="0.0151074"/>
        </inertial>
    </link>
    
    <joint name="right_elbow_joint" type="revolute">
        <parent link="right_upper_arm_link"/>
        <child link="right_fore_arm_link"/>
        <origin xyz="-0.425 0 0" rpy="0 0 0"/>
        <axis xyz="0 0 1"/>
        <limit effort="150" lower="-6.2831853" upper="6.2831853" velocity="3.14159"/>
        <!-- <limit effort="150" lower="-3.14159" upper="3.14159" velocity="3.14159"/> -->
    </joint>
    
    <link name="right_fore_arm_link">
        <visual>
            <origin xyz="0 0 0.0165" rpy="1.57079 0 -1.57079"/>
            <geometry>
                <mesh filename="../UR5/visual/forearm.dae"/>
            </geometry>
        </visual>
        <collision>
            <origin xyz="0 0 0.0165" rpy="1.57079 0 -1.57079"/>
            <geometry>
                <mesh filename="../UR5/collision/forearm.stl"/>
            </geometry>
        </collision>
        <inertial>
            <mass value="2.3300"/>
            <origin xyz="0 0 0.25"/>
            <inertia ixx="0.049443313556" ixy="0" ixz="0" iyy="0.049443313556" iyz="0" izz="0.004095"/>
        </inertial>
    </link>
    
    <joint name="right_wrist_1_joint" type="revolute">
        <parent link="right_fore_arm_link"/>
        <child link="right_wrist_1_link"/>
        <origin xyz="-0.39225 0 0.10915" rpy="0 0 0"/>
        <axis xyz="0 0 1"/>
        <limit effort="28" lower="-6.2831853" upper="6.2831853" velocity="3.14159"/>
      </joint>
    
    <link name="right_wrist_1_link">
        <visual>
            <origin xyz="0 0 -0.093" rpy="1.57079 0 0"/>
            <geometry>
                <mesh filename="../UR5/visual/wrist1.dae"/>
            </geometry>
        </visual>
        <collision>
            <origin xyz="0 0 -0.093" rpy="1.57079 0 0"/>
            <geometry>
                <mesh filename="../UR5/collision/wrist1.stl"/>
            </geometry>
        </collision>
        <inertial>
            <mass value="1.2190"/>
            <inertia ixx="0.111172755531" ixy="0" ixz="0" iyy="0.111172755531" iyz="0" izz="0.21942"/>
        </inertial>
    </link>
    
    <joint name="right_wrist_2_joint" type="revolute">
        <parent link="right_wrist_1_link"/>
        <child link="right_wrist_2_link"/>
        <origin xyz="0 -0.09465 -1.941303950897609e-11" rpy="1.570796327 0 0"/>
        <axis xyz="0 0 1"/>
        <limit effort="28" lower="-6.2831853" upper="6.2831853" velocity="3.14159"/>
    </joint>
    
    <link name="right_wrist_2_link">
        <visual>
            <origin xyz="0 0 -0.095" rpy="0 0 0"/>
            <geometry>
                <mesh filename="../UR5/visual/wrist2.dae"/>
            </geometry>
        </visual>
        <collision>
            <origin xyz="0 0 -0.095" rpy="0 0 0"/>
            <geometry>
                <mesh filename="../UR5/collision/wrist2.stl"/>
            </geometry>
        </collision>
        <inertial>
            <mass value="1.2190"/>
            <inertia ixx="0.111172755531" ixy="0" ixz="0" iyy="0.111172755531" iyz="0" izz="0.21942"/>
        </inertial>
    </link>
    
    <joint name="right_wrist_3_joint" type="revolute">
        <parent link="right_wrist_2_link"/>
        <child link="right_wrist_3_link"/>
        <origin xyz="0 0.0823 -1.688001216681175e-11" rpy="1.570796326589793 3.141592653589793 3.141592653589793"/>
        <axis xyz="0 0 1"/>
        <limit effort="28" lower="-6.2831853" upper="6.2831853" velocity="3.14159"/>
    </joint>
    
    <link name="right_wrist_3_link">
        <visual>
            <origin xyz="0 0 -0.0818" rpy="1.57079 0 0"/>
            <geometry>
                <mesh filename="../UR5/visual/wrist3.dae"/>
            </geometry>
        </visual>
        <collision>
            <origin xyz="0 0 -0.0818" rpy="1.57079 0 0"/>
            <geometry>
                <mesh filename="../UR5/collision/wrist3.stl"/>
            </geometry>
        </collision>
        <inertial>
            <mass value="0.1879"/>
            <inertia ixx="0.0171364731454" ixy="0" ixz="0" iyy="0.0171364731454" iyz="0" izz="0.033822"/>
        </inertial>
    </link>

    <!-- END: ARM RIGHT -->

    <!-- BEGIN: ARM LEFT -->

    <joint name="left_base_link" type="fixed">
        <parent link="madar_base_link"/>
        <child link="left_base_link"/>
        <origin xyz="-0.256 0.0 1.389" rpy="-3.142 0.7874 0.000"/>
    </joint>

    <link name="left_base_link">
        <visual>
            <origin xyz="0 0 0" rpy="0 0 3.14159"/>
            <geometry>
                <mesh filename="../UR5/visual/base.dae"/>
            </geometry>
        </visual>
        <collision>
            <origin xyz="0 0 0" rpy="0 0 3.14159"/>
            <geometry>
                <mesh filename="../UR5/collision/base.stl"/>
            </geometry>
        </collision>
        <inertial>
            <mass value="4.0000"/>
            <inertia ixx="0.00443333156" ixy="0" ixz="0" iyy="0.00443333156" iyz="0" izz="0.0072"/>
        </inertial>
    </link>
    
    <joint name="left_shoulder_pan_joint" type="revolute">
        <parent link="left_base_link"/>
        <child link="left_shoulder_link"/>
        <origin xyz="0 0 0.089159" rpy="0 0 0"/>
        <axis xyz="0 0 1"/>
        <limit effort="150" lower="-6.2831853" upper="6.2831853" velocity="3.14159"/>
    </joint>
    
    <link name="left_shoulder_link">
        <visual>
            <origin xyz="0 0 0" rpy="0 0 3.14159"/>
            <geometry>
                <mesh filename="../UR5/visual/shoulder.dae"/>
            </geometry>
        </visual>
        <collision>
            <origin xyz="0 0 0" rpy="0 0 3.14159"/>
            <geometry>
                <mesh filename="../UR5/collision/shoulder.stl"/>
            </geometry>
        </collision>
        <inertial>
            <mass value="3.7000"/>
            <inertia ixx="0.010267495893" ixy="0" ixz="0" iyy="0.010267495893" iyz="0" izz="0.00666"/>
        </inertial>
    </link>
    
    <joint name="left_shoulder_lift_joint" type="revolute">
        <parent link="left_shoulder_link"/>
        <child link="left_upper_arm_link"/>
        <origin xyz="0 0 0" rpy="1.570796327 0 0"/>
        <axis xyz="0 0 1"/>
        <limit effort="150" lower="-6.2831853" upper="6.2831853" velocity="3.14159"/>
    </joint>
    
    <link name="left_upper_arm_link">
        <visual>
            <origin xyz="0 0 0.13585" rpy="1.57079 0 -1.57079"/>
            <geometry>
                <mesh filename="../UR5/visual/upperarm.dae"/>
            </geometry>
        </visual>
        <collision>
            <origin xyz="0 0 0.13585" rpy="1.57079 0 -1.57079"/>
            <geometry>
                <mesh filename="../UR5/collision/upperarm.stl"/>
            </geometry>
        </collision>
        <inertial>
          <mass value="8.3930"/>
          <origin xyz="0 0 0.28"/>
          <inertia ixx="0.22689067591" ixy="0" ixz="0" iyy="0.22689067591" iyz="0" izz="0.0151074"/>
        </inertial>
    </link>
    
    <joint name="left_elbow_joint" type="revolute">
        <parent link="left_upper_arm_link"/>
        <child link="left_fore_arm_link"/>
        <origin xyz="-0.425 0 0" rpy="0 0 0"/>
        <axis xyz="0 0 1"/>
        <limit effort="150" lower="-6.2831853" upper="6.2831853" velocity="3.14159"/>
    </joint>
    
    <link name="left_fore_arm_link">
        <visual>
            <origin xyz="0 0 0.0165" rpy="1.57079 0 -1.57079"/>
            <geometry>
                <mesh filename="../UR5/visual/forearm.dae"/>
            </geometry>
        </visual>
        <collision>
            <origin xyz="0 0 0.0165" rpy="1.57079 0 -1.57079"/>
            <geometry>
                <mesh filename="../UR5/collision/forearm.stl"/>
            </geometry>
        </collision>
        <inertial>
            <mass value="2.3300"/>
            <origin xyz="0 0 0.25"/>
            <inertia ixx="0.049443313556" ixy="0" ixz="0" iyy="0.049443313556" iyz="0" izz="0.004095"/>
        </inertial>
    </link>
    
    <joint name="left_wrist_1_joint" type="revolute">
        <parent link="left_fore_arm_link"/>
        <child link="left_wrist_1_link"/>
        <origin xyz="-0.39225 0 0.10915" rpy="0 0 0"/>
        <axis xyz="0 0 1"/>
        <limit effort="28" lower="-6.2831853" upper="6.2831853" velocity="3.14159"/>
      </joint>
    
    <link name="left_wrist_1_link">
        <visual>
            <origin xyz="0 0 -0.093" rpy="1.57079 0 0"/>
            <geometry>
                <mesh filename="../UR5/visual/wrist1.dae"/>
            </geometry>
        </visual>
        <collision>
            <origin xyz="0 0 -0.093" rpy="1.57079 0 0"/>
            <geometry>
                <mesh filename="../UR5/collision/wrist1.stl"/>
            </geometry>
        </collision>
        <inertial>
            <mass value="1.2190"/>
            <inertia ixx="0.111172755531" ixy="0" ixz="0" iyy="0.111172755531" iyz="0" izz="0.21942"/>
        </inertial>
    </link>
    
    <joint name="left_wrist_2_joint" type="revolute">
        <parent link="left_wrist_1_link"/>
        <child link="left_wrist_2_link"/>
        <origin xyz="0 -0.09465 -1.941303950897609e-11" rpy="1.570796327 0 0"/>
        <axis xyz="0 0 1"/>
        <limit effort="28" lower="-6.2831853" upper="6.2831853" velocity="3.14159"/>
    </joint>
    
    <link name="left_wrist_2_link">
        <visual>
            <origin xyz="0 0 -0.095" rpy="0 0 0"/>
            <geometry>
                <mesh filename="../UR5/visual/wrist2.dae"/>
            </geometry>
        </visual>
        <collision>
            <origin xyz="0 0 -0.095" rpy="0 0 0"/>
            <geometry>
                <mesh filename="../UR5/collision/wrist2.stl"/>
            </geometry>
        </collision>
        <inertial>
            <mass value="1.2190"/>
            <inertia ixx="0.111172755531" ixy="0" ixz="0" iyy="0.111172755531" iyz="0" izz="0.21942"/>
        </inertial>
    </link>
    
    <joint name="left_wrist_3_joint" type="revolute">
        <parent link="left_wrist_2_link"/>
        <child link="left_wrist_3_link"/>
        <origin xyz="0 0.0823 -1.688001216681175e-11" rpy="1.570796326589793 3.141592653589793 3.141592653589793"/>
        <axis xyz="0 0 1"/>
        <limit effort="28" lower="-6.2831853" upper="6.2831853" velocity="3.14159"/>
    </joint>
    
    <link name="left_wrist_3_link">
        <visual>
            <origin xyz="0 0 -0.0818" rpy="1.57079 0 0"/>
            <geometry>
                <mesh filename="../UR5/visual/wrist3.dae"/>
            </geometry>
        </visual>
        <collision>
            <origin xyz="0 0 -0.0818" rpy="1.57079 0 0"/>
            <geometry>
                <mesh filename="../UR5/collision/wrist3.stl"/>
            </geometry>
        </collision>
        <inertial>
            <mass value="0.1879"/>
            <inertia ixx="0.0171364731454" ixy="0" ixz="0" iyy="0.0171364731454" iyz="0" izz="0.033822"/>
        </inertial>
    </link>

    <!-- END: ARM LEFT -->

    <!-- BEGIN: HAND RIGHT -->

    <!-- END: HAND RIGHT -->

    <!-- BEGIN: HAND LEFT -->

    <!-- END: HAND LEFT -->	

</robot>
