<?xml version="1.0" ?>
<robot name="allegro_hand_left">
  <link name="base_link">
    <visual>
      <geometry>
        <mesh filename="AllegroHand/left/base_link_left.wrl" scale="0.001 0.001 0.001"/>
      </geometry>
    </visual>
    <collision>
      <material name="black">
        <color rgba="0.2 0.2 0.2 1"/>
      </material>
      <origin xyz="-0.009300 0 -0.0475"/>
      <geometry>
        <box size="0.0408 0.1130 0.095"/>
      </geometry>
    </collision>
  </link>
  <link name="link_8.0">
    <visual>
      <geometry>
        <mesh filename="AllegroHand/left/link_0_0.wrl" scale="0.001 0.001 0.001"/>
      </geometry>
      <origin xyz="0 0 0.0164"/>
    </visual>
    <collision>
      <material name="black">
      <geometry>
        <box size="0.0196 0.0275 0.0164"/>
      </geometry>
      <origin xyz="0 0 0.0082"/>
    </collision>
  </link>
  <joint name="joint_8.0" type="revolute">
    <axis xyz="0 0 1"/>
    <limit effort="1" lower="-0.47" upper="0.47" velocity="1"/>
    <parent link="base_link"/>
    <child link="link_8.0"/>
    <origin rpy="-0.08726646255 0 0" xyz="0 0.0435 -0.001542"/>
  </joint>
  <link name="link_9.0">
    <visual>
      <geometry>
        <mesh filename="AllegroHand/left/link_1_0.wrl" scale="0.001 0.001 0.001"/>
      </geometry>
      <origin rpy="1.5707963 -1.5707963 0"/>
    </visual>
    <collision>
      <material name="black">
      <geometry>
        <box size="0.0196 0.0275 0.054"/>
      </geometry>
      <origin xyz="0 0 0.027"/>
    </collision>
  </link>
  <joint name="joint_9.0" type="revolute">
    <limit effort="1" lower="-0.196" upper="1.61" velocity="1"/>
    <axis xyz="0 1 0"/>
    <parent link="link_8.0"/>
    <child link="link_9.0"/>
    <origin xyz="0 0 0.0164"/>
  </joint>
  <link name="link_10.0">
    <visual>
      <geometry>
        <mesh filename="AllegroHand/left/link_2_0.wrl" scale="0.001 0.001 0.001"/>
      </geometry>
      <origin rpy="-1.5707963 -1.5707963 0"/>
    </visual>
    <collision>
      <material name="black">
      <geometry>
        <box size="0.0196 0.0275 0.0384"/>
      </geometry>
      <origin xyz="0 0 0.0192"/>
    </collision>
  </link>
  <joint name="joint_10.0" type="revolute">
    <axis xyz="0 1 0"/>
    <limit effort="1" lower="-0.174" upper="1.709" velocity="1"/>
    <parent link="link_9.0"/>
    <child link="link_10.0"/>
    <origin xyz="0 0 0.054"/>
  </joint>
  <link name="link_11.0">
    <visual>
      <geometry>
        <mesh filename="AllegroHand/left/link_3_0.wrl" scale="0.001 0.001 0.001"/>
      </geometry>
      <origin rpy="-1.5707963 -1.5707963 0"/>
    </visual>
    <collision>
      <material name="black">
      <geometry>
        <box size="0.0196 0.0275 0.0267"/>
      </geometry>
      <origin xyz="0 0 0.01335"/>
    </collision>
  </link>
  <joint name="joint_11.0" type="revolute">
    <axis xyz="0 1 0"/>
    <limit effort="1" lower="-0.227" upper="1.618" velocity="1"/>
    <parent link="link_10.0"/>
    <child link="link_11.0"/>
    <origin xyz="0 0 0.0384"/>
  </joint>
  <link name="link_11.0_tip">
    <visual>
      <geometry>
        <mesh filename="AllegroHand/right/link_3_0_tip.wrl" scale="0.001 0.001 0.001"/>
      </geometry>
      <origin rpy="1.5707963 -1.5707963 0" xyz="0 0 -0.01" />
    </visual>
    <collision>
      <material name="white">
      <geometry>
        <sphere radius="0.012" />
      </geometry>
    </collision>
  </link>
  <joint name="joint_11.0_tip" type="fixed">
    <parent link="link_11.0"/>
    <child link="link_11.0_tip"/>
    <origin xyz="0 0 0.0267"/>
  </joint>
  <link name="link_4.0">
    <visual>
      <geometry>
        <mesh filename="AllegroHand/left/link_0_0.wrl" scale="0.001 0.001 0.001"/>
      </geometry>
      <origin xyz="0 0 0.0164"/>
    </visual>
    <collision>
      <material name="black">
      <geometry>
        <box size="0.0196 0.0275 0.0164"/>
      </geometry>
      <origin xyz="0 0 0.0082"/>
    </collision>
  </link>
  <joint name="joint_4.0" type="revolute">
    <axis xyz="0 0 1"/>
    <limit effort="1" lower="-0.47" upper="0.47" velocity="1"/>
    <parent link="base_link"/>
    <child link="link_4.0"/>
    <origin xyz="0 0 0.0007"/>
  </joint>
  <link name="link_5.0">
    <visual>
      <geometry>
        <mesh filename="AllegroHand/left/link_1_0.wrl" scale="0.001 0.001 0.001"/>
      </geometry>
      <origin rpy="1.5707963 -1.5707963 0"/>
    </visual>
    <collision>
      <material name="black">
      <geometry>
        <box size="0.0196 0.0275 0.054"/>
      </geometry>
      <origin xyz="0 0 0.027"/>
    </collision>
  </link>
  <joint name="joint_5.0" type="revolute">
    <limit effort="1" lower="-0.196" upper="1.61" velocity="1"/>
    <axis xyz="0 1 0"/>
    <parent link="link_4.0"/>
    <child link="link_5.0"/>
    <origin xyz="0 0 0.0164"/>
  </joint>
  <link name="link_6.0">
    <visual>
      <geometry>
        <mesh filename="AllegroHand/left/link_2_0.wrl" scale="0.001 0.001 0.001"/>
      </geometry>
      <origin rpy="-1.5707963 -1.5707963 0"/>
    </visual>
    <collision>
      <material name="black">
      <geometry>
        <box size="0.0196 0.0275 0.0384"/>
      </geometry>
      <origin xyz="0 0 0.0192"/>
    </collision>
  </link>
  <joint name="joint_6.0" type="revolute">
    <axis xyz="0 1 0"/>
    <limit effort="1" lower="-0.174" upper="1.709" velocity="1"/>
    <parent link="link_5.0"/>
    <child link="link_6.0"/>
    <origin xyz="0 0 0.054"/>
  </joint>
  <link name="link_7.0">
    <visual>
      <geometry>
        <mesh filename="AllegroHand/left/link_3_0.wrl" scale="0.001 0.001 0.001"/>
      </geometry>
      <origin rpy="-1.5707963 -1.5707963 0"/>
    </visual>
    <collision>
      <material name="black">
      <geometry>
        <box size="0.0196 0.0275 0.0267"/>
      </geometry>
      <origin xyz="0 0 0.01335"/>
    </collision>
  </link>
  <joint name="joint_7.0" type="revolute">
    <axis xyz="0 1 0"/>
    <limit effort="1" lower="-0.227" upper="1.618" velocity="1"/>
    <parent link="link_6.0"/>
    <child link="link_7.0"/>
    <origin xyz="0 0 0.0384"/>
  </joint>
  <link name="link_7.0_tip">
    <visual>
      <geometry>
        <mesh filename="AllegroHand/right/link_3_0_tip.wrl" scale="0.001 0.001 0.001"/>
      </geometry>
      <origin rpy="1.5707963 -1.5707963 0" xyz="0 0 -0.01" />
    </visual>
    <collision>
      <material name="white">
        <color rgba=".9 .9 .9 1" />
      </material>
      <geometry>
        <sphere radius="0.012" />
      </geometry>
    </collision>
  </link>
  <joint name="joint_7.0_tip" type="fixed">
    <parent link="link_7.0"/>
    <child link="link_7.0_tip"/>
    <origin xyz="0 0 0.0267"/>
  </joint>
  <link name="link_0.0">
    <visual>
      <geometry>
        <mesh filename="AllegroHand/left/link_0_0.wrl" scale="0.001 0.001 0.001"/>
      </geometry>
      <origin xyz="0 0 0.0164"/>
    </visual>
    <collision>
      <material name="black">
      <geometry>
        <box size="0.0196 0.0275 0.0164"/>
      </geometry>
      <origin xyz="0 0 0.0082"/>
    </collision>
  </link>
  <joint name="joint_0.0" type="revolute">
    <axis xyz="0 0 1"/>
    <limit effort="1" lower="-0.47" upper="0.47" velocity="1"/>
    <parent link="base_link"/>
    <child link="link_0.0"/>
    <origin rpy="0.08726646255 0 0" xyz="0 -0.0435 -0.001542"/>
  </joint>
  <link name="link_1.0">
    <visual>
      <geometry>
        <mesh filename="AllegroHand/left/link_1_0.wrl" scale="0.001 0.001 0.001"/>
      </geometry>
      <origin rpy="1.5707963 -1.5707963 0"/>
    </visual>
    <collision>
      <material name="black">
      <geometry>
        <box size="0.0196 0.0275 0.054"/>
      </geometry>
      <origin xyz="0 0 0.027"/>
    </collision>
  </link>
  <joint name="joint_1.0" type="revolute">
    <limit effort="1" lower="-0.196" upper="1.61" velocity="1"/>
    <axis xyz="0 1 0"/>
    <parent link="link_0.0"/>
    <child link="link_1.0"/>
    <origin xyz="0 0 0.0164"/>
  </joint>
  <link name="link_2.0">
    <visual>
      <geometry>
        <mesh filename="AllegroHand/left/link_2_0.wrl" scale="0.001 0.001 0.001"/>
      </geometry>
      <origin rpy="-1.5707963 -1.5707963 0"/>
    </visual>
    <collision>
      <material name="black">
      <geometry>
        <box size="0.0196 0.0275 0.0384"/>
      </geometry>
      <origin xyz="0 0 0.0192"/>
    </collision>
  </link>
  <joint name="joint_2.0" type="revolute">
    <axis xyz="0 1 0"/>
    <limit effort="1" lower="-0.174" upper="1.709" velocity="1"/>
    <parent link="link_1.0"/>
    <child link="link_2.0"/>
    <origin xyz="0 0 0.054"/>
  </joint>
  <link name="link_3.0">
    <visual>
      <geometry>
        <mesh filename="AllegroHand/left/link_3_0.wrl" scale="0.001 0.001 0.001"/>
      </geometry>
      <origin rpy="-1.5707963 -1.5707963 0"/>
    </visual>
    <collision>
      <material name="black">
      <geometry>
        <box size="0.0196 0.0275 0.0267"/>
      </geometry>
      <origin xyz="0 0 0.01335"/>
    </collision>
  </link>
  <joint name="joint_3.0" type="revolute">
    <axis xyz="0 1 0"/>
    <limit effort="1" lower="-0.227" upper="1.618" velocity="1"/>
    <parent link="link_2.0"/>
    <child link="link_3.0"/>
    <origin xyz="0 0 0.0384"/>
  </joint>
  <link name="link_3.0_tip">
    <visual>
      <geometry>
        <mesh filename="AllegroHand/right/link_3_0_tip.wrl" scale="0.001 0.001 0.001"/>
      </geometry>
      <origin rpy="1.5707963 -1.5707963 0" xyz="0 0 -0.01" />
    </visual>
    <collision>
      <material name="white">
      <geometry>
        <sphere radius="0.012" />
      </geometry>
    </collision>
  </link>
  <joint name="joint_3.0_tip" type="fixed">
    <parent link="link_3.0"/>
    <child link="link_3.0_tip"/>
    <origin xyz="0 0 0.0267"/>
  </joint>
  <link name="link_12.0">
    <visual>
      <geometry>
        <mesh filename="AllegroHand/left/link_12_0_left.wrl" scale="0.001 0.001 0.001"/>
      </geometry>
      <origin rpy="-1.570796327 0 -1.570796327" xyz="-0.02775 0 0"/>
    </visual>
    <collision>
      <material name="black">
      <geometry>
        <box size="0.0358 0.034 0.0455"/>
      </geometry>
      <origin xyz="-0.0179 -0.009 0.0145"/>
    </collision>
  </link>
  <joint name="joint_12.0" type="revolute">
    <axis xyz="1 0 0"/>
    <limit effort="1" lower="0.263" upper="1.396" velocity="1"/>
    <parent link="base_link"/>
    <child link="link_12.0"/>
    <origin rpy="0 -1.65806278845 1.5707963259" xyz="-0.0182 -0.019333 -0.045987"/>
  </joint>
  <link name="link_13.0">
    <visual>
      <geometry>
        <mesh filename="AllegroHand/left/link_13_0.wrl" scale="0.001 0.001 0.001"/>
      </geometry>
      <origin xyz="0 0 0.016000001" rpy="3.141592654 0 3.141592654"/>
    </visual>
    <collision>
      <material name="black">
      <geometry>
        <box size="0.0196 0.0275 0.0177"/>
      </geometry>
      <origin xyz="0 0 0.00885"/>
    </collision>
  </link>
  <joint name="joint_13.0" type="revolute">
    <axis xyz="0 0 -1"/>
    <limit effort="1" lower="-0.105" upper="1.163" velocity="1"/>
    <parent link="link_12.0"/>
    <child link="link_13.0"/>
    <origin xyz="-0.027 -0.005 0.0399"/>
  </joint>
  <link name="link_14.0">
    <visual>
      <geometry>
        <mesh filename="AllegroHand/left/link_14_0.wrl" scale="0.001 0.001 0.001"/>
      </geometry>
      <origin rpy="-1.5707963259 -1.5707963259 0"/>
    </visual>
    <collision>
      <material name="black">
      <geometry>
        <box size="0.0196 0.0275 0.0514"/>
      </geometry>
      <origin xyz="0 0 0.0257"/>
    </collision>
  </link>
  <joint name="joint_14.0" type="revolute">
    <axis xyz="0 1 0"/>
    <limit effort="1" lower="-0.189" upper="1.644" velocity="1"/>
    <parent link="link_13.0"/>
    <child link="link_14.0"/>
    <origin xyz="0 0 0.0177"/>
  </joint>
  <link name="link_15.0">
    <visual>
      <geometry>
        <mesh filename="AllegroHand/left/link_15_0.wrl" scale="0.001 0.001 0.001"/>
      </geometry>
      <origin rpy="1.5707963259 -1.5707963259 0"/>
    </visual>
    <collision>
      <material name="black">
      <geometry>
        <box size="0.0196 0.0275 0.0423"/>
      </geometry>
      <origin xyz="0 0 0.02115"/>
    </collision>
  </link>
  <joint name="joint_15.0" type="revolute">
    <axis xyz="0 1 0"/>
    <limit effort="1" lower="-0.162" upper="1.719" velocity="1"/>
    <parent link="link_14.0"/>
    <child link="link_15.0"/>
    <origin xyz="0 0 0.0514"/>
  </joint>
  <link name="link_15.0_tip">
    <visual>
      <geometry>
        <mesh filename="AllegroHand/right/link_3_0_tip.wrl" scale="0.001 0.001 0.001"/>
      </geometry>
      <origin rpy="1.5707963 -1.5707963 0" xyz="0 0 -0.01" />
    </visual>
    <collision>
      <material name="white">
      <geometry>
        <sphere radius="0.012" />
      </geometry>
    </collision>
  </link>
  <joint name="joint_15.0_tip" type="fixed">
    <parent link="link_15.0"/>
    <child link="link_15.0_tip"/>
    <origin xyz="0 0 0.0423"/>
  </joint>
</robot>
