<?xml version="1.0"?>

<robot name="kuka_lwr_pg70_gripper">
	<WeightSE3 rho_t="0.05" rho_r="0.05" />
  <link name="base">
    <inertial>
      <mass value="2.7"/>
      <origin rpy="0 0 0" xyz="0 0 0.055"/>
      <inertia ixx="0.00603" ixy="0" ixz="0" iyy="0.00603" iyz="0" izz="0.006615"/>
    </inertial>
    <collision>
      <origin rpy="0 0 0" xyz="0 0 0.055"/>
      <geometry>
        <cylinder length="0.11" radius="0.08"/>
      </geometry>
      <material>
	<color rgba="1 0.5 0 1"/>
      </material>
    </collision>
    <visual>
      <origin rpy="0 0 0" xyz="0 0 0"/>
      <geometry>
        <mesh filename="kuka_lwr/base.wrl" scale="0.001 0.001 0.001"/>
      </geometry>
    </visual>
  </link>
  <link name="link1">
    <inertial>
      <mass value="2.7082"/>
      <origin rpy="0 0 0" xyz="0 0.01698 -0.05913"/>
      <inertia ixx="0.0123449" ixy="0" ixz="0" iyy="0.0123449" iyz="0" izz="3.9396351"/>
    </inertial>
    <collision>
      <origin rpy="0 0 0" xyz="0 0 -0.1"/>
      <geometry>
        <cylinder length="0.2" radius="0.08"/>
      </geometry>
      <material>
	<color rgba="1 0.5 0 1"/>
      </material>
    </collision>
    <collision>
      <origin rpy="0 0 0" xyz="0 0 0"/>
      <geometry>
        <sphere radius="0.1"/>
      </geometry>
      <material>
	<color rgba="1 0.5 0 1"/>
      </material>
    </collision>
    <visual>
      <origin rpy="0 0 0" xyz="0 0 0"/>
      <geometry>
        <mesh filename="kuka_lwr/link1.wrl" scale="0.001 0.001 0.001"/>
      </geometry>
    </visual>
  </link>
  <link name="link2">
    <inertial>
      <mass value="2.71"/>
      <origin rpy="0 0 0" xyz="0 0.1109 0.0141"/>
      <inertia ixx="0.0123531" ixy="0" ixz="0" iyy="0.0123531" iyz="0" izz="3.9396395"/>
    </inertial>
    <collision>
      <origin rpy="-1.57079632679 0 0" xyz="0 0.1 0"/>
      <geometry>
        <cylinder length="0.2" radius="0.08"/>
      </geometry>
      <material>
	<color rgba="1 0.5 0 1"/>
      </material>
    </collision>
    <visual>
      <origin rpy="0 0 0" xyz="0 0 0"/>
      <geometry>
        <mesh filename="kuka_lwr/link2.wrl" scale="0.001 0.001 0.001"/>
      </geometry>
    </visual>
  </link>
  <link name="link3">
    <inertial>
      <mass value="2.5374"/>
      <origin rpy="0 0 0" xyz="0 -0.01628 0.06621"/>
      <inertia ixx="0.0115663" ixy="0" ixz="0" iyy="0.0115663" iyz="0" izz="1.5369966"/>
    </inertial>
    <collision>
      <origin rpy="0 0 0" xyz="0 0 0.1"/>
      <geometry>
        <cylinder length="0.2" radius="0.08"/>
      </geometry>
      <material>
	<color rgba="1 0.5 0 1"/>
      </material>
    </collision>
    <collision>
      <origin rpy="0 0 0" xyz="0 0 0.2"/>
      <geometry>
        <sphere radius="0.1"/>
      </geometry>
      <material>
	<color rgba="1 0.5 0 1"/>
      </material>
    </collision>
    <visual>
      <origin rpy="0 0 0" xyz="0 0 0.2"/>
      <geometry>
        <mesh filename="kuka_lwr/link3.wrl" scale="0.001 0.001 0.001"/>
      </geometry>
    </visual>
  </link>
  <link name="link4">
    <inertial>
      <mass value="2.5053"/>
      <origin rpy="0 0 0" xyz="0 -0.10538 0.01525"/>
      <inertia ixx="0.01142" ixy="0" ixz="0" iyy="0.01142" iyz="0" izz="1.536918"/>
    </inertial>
    <collision>
      <origin rpy="-1.57079632679 0 0" xyz="0 -0.1 0"/>
      <geometry>
        <cylinder length="0.2" radius="0.08"/>
      </geometry>
      <material>
	<color rgba="1 0.5 0 1"/>
      </material>
    </collision>
    <visual>
      <origin rpy="3.141592654 3.141592654 0" xyz="0 0 0"/>
      <geometry>
        <mesh filename="kuka_lwr/link4.wrl" scale="0.001 0.001 0.001"/>
      </geometry>
    </visual>
  </link>
  <joint type="revolute" name="joint1">
    <parent link="base"/>
    <child link="link1"/>
    <origin rpy="0 0 0" xyz="0 0 0.31"/>
    <axis xyz="0 0 1"/>
    <limit velocity="1.6" effort="150" lower="-2.96705972839" upper="2.96705972839"/>
  </joint>
  <joint type="revolute" name="joint2">
    <parent link="link1"/>
    <child link="link2"/>
    <origin rpy="1.57079632679 0 0" xyz="0 0 0"/>
    <axis xyz="0 0 1"/>
    <limit velocity="1.6" effort="150" lower="-2.09439510239" upper="2.09439510239"/>
  </joint>
  <joint type="revolute" name="joint3">
    <parent link="link2"/>
    <child link="link3"/>
    <origin rpy="-1.57079632679 0 0" xyz="0 0.2 0"/>
    <axis xyz="0 0 1"/>
    <limit velocity="1.6" effort="150" lower="-2.96705972839" upper="2.96705972839"/>
  </joint>
  <joint type="revolute" name="joint4">
    <parent link="link3"/>
    <child link="link4"/>
    <origin rpy="-1.57079632679 0 0" xyz="0 0 0.2"/>
    <axis xyz="0 0 1"/>
    <limit velocity="1.6" effort="150" lower="-2.09439510239" upper="2.09439510239"/>
  </joint>
 </robot>
