<?xml version="1.0" ?>
<!-- =================================================================================== -->
<!-- |    This document was autogenerated by xacro from tx90_macro.xacro               | -->
<!-- |    EDITING THIS FILE BY HAND IS NOT RECOMMENDED                                 | -->
<!-- =================================================================================== -->
<robot name="TX90_robotniq">
  <!-- colours based on RAL values supplied by Staubli -->
  <!-- all RAL colours converted using http://www.visual-graphics.de/en/customer-care/ral-colours -->
  <!-- default colours for robots -->
  <!-- links: main serial chain -->
  <link name="base_link">
    <visual>
      <origin rpy="0 0 0" xyz="0 0 0"/>
      <geometry>
        <mesh filename="tx90/meshes/visual/base_link.stl"/>
      </geometry>
      <material name="">
        <color rgba="1.0 0.6078431372549019 0.0 1.0"/>
      </material>
    </visual>
    <collision>
      <origin rpy="0 0 0" xyz="0 0 0"/>
      <geometry>
        <mesh filename="tx90/meshes/collision/base_link.stl"/>
      </geometry>
    </collision>
    <inertial>
      <mass value="10.733459"/>
      <origin rpy="0.0 0.0 0.0" xyz="0.014288 0.000001 0.122264"/>
      <inertia ixx="0.096590" ixy="-0.000005" ixz="-0.003803" iyy="0.087591" iyz="-0.000001" izz="0.081632"/>
    </inertial>
  </link>
  <link name="link_1">
    <visual>
      <origin rpy="0 0 0" xyz="0 0 0"/>
      <geometry>
        <mesh filename="tx90/meshes/visual/link_1.stl"/>
      </geometry>
      <material name="">
        <color rgba="1.0 0.6078431372549019 0.0 1.0"/>
      </material>
    </visual>
    <collision>
      <origin rpy="0 0 0" xyz="0 0 0"/>
      <geometry>
        <mesh filename="tx90/meshes/collision/link_1.stl"/>
      </geometry>
    </collision>
    <inertial>
      <mass value="16.934564"/>
      <origin rpy="0.0 0.0 0.0" xyz="0.019143 0.024764 -0.064596"/>
      <inertia ixx="0.222318" ixy="0.016499" ixz="0.023794" iyy="0.208959" iyz="0.031663" izz="0.157081"/>
    </inertial>
  </link>
  <link name="link_2">
    <visual>
      <origin rpy="0 0 0" xyz="0 0 0"/>
      <geometry>
        <mesh filename="tx90/meshes/visual/link_2.stl"/>
      </geometry>
      <material name="">
        <color rgba="1.0 0.6078431372549019 0.0 1.0"/>
      </material>
    </visual>
    <collision>
      <origin rpy="0 0 0" xyz="0 0 0"/>
      <geometry>
        <mesh filename="tx90/meshes/collision/link_2.stl"/>
      </geometry>
    </collision>
    <inertial>
      <mass value="12.98711"/>
      <origin rpy="0.0 0.0 0.0" xyz="-0.000008 0.221181 0.173052"/>
      <inertia ixx="0.425299" ixy="0.000005" ixz="-0.000004" iyy="0.452311" iyz="-0.002920" izz="0.054493"/>
    </inertial>
  </link>
  <link name="link_3">
    <visual>
      <origin rpy="0 0 0" xyz="0 0 0"/>
      <geometry>
        <mesh filename="tx90/meshes/visual/link_3.stl"/>
      </geometry>
      <material name="">
        <color rgba="1.0 0.6078431372549019 0.0 1.0"/>
      </material>
    </visual>
    <collision>
      <origin rpy="0 0 0" xyz="0 0 0"/>
      <geometry>
        <mesh filename="tx90/meshes/collision/link_3.stl"/>
      </geometry>
    </collision>
    <inertial>
      <mass value="7.50151"/>
      <origin rpy="0.0 0.0 0.0" xyz="0.000002 0.065008 0.003572"/>
      <inertia ixx="0.058902" ixy="0.000000" ixz="0.000001" iyy="0.056884" iyz="-0.003672" izz="0.034271"/>
    </inertial>
  </link>
  <link name="link_4">
    <visual>
      <origin rpy="0 0 0" xyz="0 0 0"/>
      <geometry>
        <mesh filename="tx90/meshes/visual/link_4.stl"/>
      </geometry>
      <material name="">
        <color rgba="1.0 0.6078431372549019 0.0 1.0"/>
      </material>
    </visual>
    <collision>
      <origin rpy="0 0 0" xyz="0 0 0"/>
      <geometry>
        <mesh filename="tx90/meshes/collision/link_4.stl"/>
      </geometry>
    </collision>
    <inertial>
      <mass value="4.54015"/>
      <origin rpy="0.0 0.0 0.0" xyz="-0.002488 0.049988 0.296156"/>
      <inertia ixx="0.043246" ixy="0.000003" ixz="-0.000683" iyy="0.038394" iyz="-0.000004" izz="0.014525"/>
    </inertial>
  </link>
  <link name="link_5">
    <visual>
      <origin rpy="0 0 0" xyz="0 0 0"/>
      <geometry>
        <mesh filename="tx90/meshes/visual/link_5.stl"/>
      </geometry>
      <material name="">
        <color rgba="0.5294117647058824 0.5215686274509804 0.5058823529411764 1.0"/>
      </material>
    </visual>
    <collision>
      <origin rpy="0 0 0" xyz="0 0 0"/>
      <geometry>
        <mesh filename="tx90/meshes/collision/link_5.stl"/>
      </geometry>
    </collision>
    <inertial>
      <mass value="0.56876"/>
      <origin rpy="0.0 0.0 0.0" xyz="0.000000 0.049931 0.222823"/>
      <inertia ixx="0.001084" ixy="0.000000" ixz="0.000000" iyy="0.001123" iyz="0.000001" izz="0.000383"/>
    </inertial>
  </link>
  <link name="link_6">
    <visual>
      <origin rpy="0 0 0" xyz="0 0 0"/>
      <geometry>
        <mesh filename="tx90/meshes/visual/link_6.stl"/>
      </geometry>
      <material name="">
        <color rgba="0.5294117647058824 0.5215686274509804 0.5058823529411764 1.0"/>
      </material>
    </visual>
    <collision>
      <origin rpy="0 0 0" xyz="0 0 0"/>
      <geometry>
        <mesh filename="tx90/meshes/collision/link_6.stl"/>
      </geometry>
    </collision>
    <inertial>
      <mass value="0.03098"/>
      <origin rpy="0.0 0.0 0.0" xyz="-0.000243 0.050000 -0.006293"/>
      <inertia ixx="0.000012" ixy="0.000000" ixz="0.000000" iyy="0.000011" iyz="0.000000" izz="0.000022"/>
    </inertial>
  </link>
  <!-- joints: main serial chain -->
  <joint name="joint_1" type="revolute">
    <origin rpy="0 0 0" xyz="0 0 0.478"/>
    <parent link="base_link"/>
    <child link="link_1"/>
    <axis xyz="0 0 1"/>
    <!-- from Staubli instruction manual:
      (1) effort limit = 318 Nm if floor mounted
      (2) effort limit = 111 Nm if wall mounted -->
    <limit effort="318.0" lower="-3.141592653589793" upper="3.141592653589793" velocity="6.981317007977318"/>
    <dynamics damping="0.0" friction="0.0"/>
  </joint>
  <joint name="joint_2" type="revolute">
    <origin rpy="0 0 0" xyz="0.050 0 0"/>
    <parent link="link_1"/>
    <child link="link_2"/>
    <axis xyz="0 1 0"/>
    <limit effort="166.0" lower="-2.2689280275926285" upper="2.5743606466916362" velocity="6.981317007977318"/>
    <dynamics damping="0.0" friction="0.0"/>
  </joint>
  <joint name="joint_3" type="revolute">
    <origin rpy="0 0 0" xyz="0 0.05 0.425"/>
    <parent link="link_2"/>
    <child link="link_3"/>
    <axis xyz="0 1 0"/>
    <limit effort="76.0" lower="-2.530727415391778" upper="2.530727415391778" velocity="7.504915783575617"/>
    <dynamics damping="0.0" friction="0.0"/>
  </joint>
  <joint name="joint_4" type="revolute">
    <origin rpy="0 0 0" xyz="0 0 0"/>
    <parent link="link_3"/>
    <child link="link_4"/>
    <axis xyz="0 0 1"/>
    <limit effort="34.0" lower="-4.71238898038469" upper="4.71238898038469" velocity="9.42477796076938"/>
    <dynamics damping="0.0" friction="0.0"/>
  </joint>
  <joint name="joint_5" type="revolute">
    <origin rpy="0 0 0" xyz="0 0 0.425"/>
    <parent link="link_4"/>
    <child link="link_5"/>
    <axis xyz="0 1 0"/>
    <limit effort="29.0" lower="-2.007128639793479" upper="2.443460952792061" velocity="8.290313946973065"/>
    <dynamics damping="0.0" friction="0.0"/>
  </joint>
  <joint name="joint_6" type="revolute">
    <origin rpy="0 0 0" xyz="0 0 0.100"/>
    <parent link="link_5"/>
    <child link="link_6"/>
    <axis xyz="0 0 1"/>
    <limit effort="11.0" lower="-4.71238898038469" upper="4.71238898038469" velocity="13.264502315156905"/>
    <dynamics damping="0.0" friction="0.0"/>
  </joint>
  <!-- ROS-Industrial 'base' frame: base_link to Staubli World Coordinates transform -->
  <!--link name="base" />
    <joint name="base_link-base" type="fixed">
      <origin xyz="0 0 0.478" rpy="0 0 0"/>
      <parent link="base_link"/>
      <child link="base"/>
    </joint-->
  <!-- ROS-Industrial 'flange' frame: attachment point for EEF models -->
  <!--link name="flange" />
    <joint name="joint_6-flange" type="fixed">
      <origin xyz="0 0 0" rpy="0 ${radians(-90.0)} 0" />
      <parent link="link_6" />
      <child link="flange" />
    </joint-->
  <!-- ROS-Industrial 'tool0' frame: all-zeros tool frame -->
  <!--link name="tool0" />
    <joint name="flange-tool0" type="fixed">
      <origin xyz="0 0 0" rpy="0 ${radians(90.0)} 0" />
      <parent link="flange" />
      <child link="tool0" />
    </joint-->
  
  <!-- Robotiq/UR coupler -->
  <joint name="coupler_joint" type="fixed">
    <parent link="link_6"/>
    <child link="coupler_link"/>
    <origin rpy="0.0 0.0 0.0" xyz="0.0 0.0 0.0"/>
  </joint>
  <link name="coupler_link">
    <visual>
      <!-- total height of coupler, minus the depth of robot end-effector shape-->
      <origin rpy="0 0 0" xyz="0 0 0.00545"/>
      <geometry>
        <cylinder length="0.0139" radius="0.0375"/>
      </geometry>
      <material name="dark_grey">
        <color rgba="0.05 0.05 0.05 1"/>
      </material>
    </visual>
    <collision>
      <origin rpy="0 0 0" xyz="0 0 0.01"/>
      <!--<origin rpy="0 0 0" xyz="0 0 0"/>-->
      <geometry>
        <cylinder length="0.0139" radius="0.0375"/>
      </geometry>
    </collision>
  </link>
  <!-- base -->
  <joint name="coupler_link_gripper_base_joint" type="fixed">
    <origin rpy="0 0 1.57079632679" xyz="0 0 0.0079"/>
    <parent link="coupler_link"/>
    <child link="gripper_base"/>
  </joint>
  <link name="gripper_base">
    <!-- inertial>
				<mass value="0.1"/>
				<origin xyz="0 0 0.055"  />
				<cylinder_inertia radius="0.06" length="0.11" mass="0.1"/>
			</inertial -->
    <visual>
      <geometry>
        <mesh filename="robotiq/visual/base.dae" scale="0.001 0.001 0.001"/>
      </geometry>
    </visual>
    <collision>
      <origin rpy="0 0 0" xyz="0 0 0.015"/>
      <geometry>
          <!--<cylinder length="0.045" radius="0.04"/>-->
        <cylinder length="0.045" radius="0.039"/>
      </geometry>
    </collision>
    <collision>
      <origin rpy="0 0 0" xyz="0 0 0.06"/>
      <geometry>
        <box size="0.03 0.04 0.06"/>
      </geometry>
    </collision>
  </link>
  
  <!-- right finger -->
  <joint name="gripper_right_driver_joint" type="revolute">
    <origin rpy="0 0 0" xyz="0 0.0306011 0.054904"/>
    <parent link="gripper_base"/>
    <child link="gripper_right_driver"/>
    <axis xyz="1 0 0"/>
    <limit effort="60" lower="0.0" upper="0.872664444444" velocity="1.91986177778"/>
  </joint>
  <link name="gripper_right_driver">
    <!-- inertial>
				<mass value="0.1"/>
				<origin xyz="0 0 0.055"  />
				<cylinder_inertia radius="0.06" length="0.11" mass="0.1"/>
			</inertial -->
    <visual>
      <geometry>
        <mesh filename="robotiq/visual/driver.dae" scale="0.001 0.001 0.001"/>
      </geometry>
    </visual>
    <collision>
      <origin rpy="-0.1 0 0" xyz="0 0.02 0"/>

      <geometry>
        <box size="0.02 0.04 0.02"/>
      </geometry>
    </collision>
  </link>
 

 <joint name="gripper_right_coupler_joint" type="fixed">
    <origin rpy="0 0 0" xyz="0 0.0315 -0.0041"/>
    <parent link="gripper_right_driver"/>
    <child link="gripper_right_coupler"/>
  </joint>
  <link name="gripper_right_coupler">
    <!-- inertial>
				<mass value="0.1"/>
				<origin xyz="0 0 0.055"  />
				<cylinder_inertia radius="0.06" length="0.11" mass="0.1"/>
			</inertial -->
    <visual>
      <geometry>
        <mesh filename="robotiq/visual/coupler.dae" scale="0.001 0.001 0.001"/>
      </geometry>
    </visual>
    <collision>
      <!--<origin rpy="-1.7 0 0" xyz="0 0.0 0.025"/>-->
      <origin rpy="-1.7 0 0" xyz="0 0.005 0.025"/>
      <material name="green">
        <color rgba="0.05 0.95 0.05 1"/>
      </material>
      <geometry>
        <!--<box size="0.03 0.065 0.02"/>-->
        <box size="0.03 0.065 0.01"/>
      </geometry>
    </collision>
  </link>

<joint name="gripper_right_follower_joint" type="revolute">
    <origin rpy="0 0 0" xyz="0 0.0061 0.0471"/>
    <parent link="gripper_right_coupler"/>
    <child link="gripper_right_follower"/>
    <axis xyz="1 0 0"/>
    <limit effort="176" lower="-2.96705911111" upper="2.96705911111" velocity="1.91986177778"/>
    <mimic joint="gripper_right_driver_joint" multiplier="-1"/>
  </joint>
  <link name="gripper_right_follower">
    <visual>
      <geometry>
        <mesh filename="robotiq/visual/follower.dae" scale="0.001 0.001 0.001"/>
      </geometry>
    </visual>
    <collision>
      <origin rpy="0 0 0" xyz="0 -0.016 0.022"/> 
      <!--<origin rpy="0 0 0" xyz="0 -0.018 0.022"/>--> 
     <material name="dark_blue">
        <color rgba="0.2 0.2 0.8 1"/>
      </material>
      <geometry>
        <box size="0.02 0.01 0.048"/>
        <!--<box size="0.02 0.015 0.048"/>-->
      </geometry>
    </collision>
  </link>

 <joint name="gripper_right_pad_joint" type="fixed">
    <parent link="gripper_right_follower"/>
    <child link="gripper_right_pad"/>
  </joint>
  <link name="gripper_right_pad">
    <!-- inertial>
				<mass value="0.1"/>
				<origin xyz="0 0 0.055"  />
				<cylinder_inertia radius="0.06" length="0.11" mass="0.1"/>
			</inertial -->
    <visual>
      <geometry>
        <mesh filename="robotiq/visual/pad.dae" scale="0.001 0.001 0.001"/>
      </geometry>
    </visual>
    <collision>
      <origin rpy="0 0 0" xyz="0 -0.022 0.031"/>
      <material name="dark_gray">
        <color rgba="0.2 0.2 0.2 1"/>
      </material>
      <geometry>
        <box size="0.02 0.004 0.036"/>
        <!--<box size="0.02 0.008 0.036"/>-->
      </geometry>
    </collision>
  </link>
  
<joint name="gripper_right_spring_link_joint" type="revolute">
    <origin rpy="0 0 0" xyz="0 0.012 0.0614"/>
    <parent link="gripper_base"/>
    <child link="gripper_right_spring_link"/>
    <axis xyz="1 0 0"/>
    <limit effort="176" lower="-2.96705911111" upper="2.96705911111" velocity="1.91986177778"/>
    <mimic joint="gripper_right_driver_joint" multiplier="1"/>
  </joint>
  <link name="gripper_right_spring_link">
    <!-- inertial>
				<mass value="0.1"/>
				<origin xyz="0 0 0.055"  />
				<cylinder_inertia radius="0.06" length="0.11" mass="0.1"/>
			</inertial -->
    <visual>
      <geometry>
        <mesh filename="robotiq/visual/spring_link.dae" scale="0.001 0.001 0.001"/>
      </geometry>
    </visual>
    <collision>
      <origin rpy="-0.7068 0 0" xyz="0 0.018 0.018"/>
      <material name="red">
        <color rgba="0.95 0.05 0.05 1"/>
      </material>
      <geometry>
        <box size="0.04 0.01 0.045"/>
        <!--<box size="0.04 0.02 0.065"/>-->
      </geometry>
    </collision>
  </link>

  <!-- left finger -->
  <joint name="gripper_left_driver_joint" type="revolute">
    <origin rpy="0 0 3.141592653589793" xyz="0 -0.0306011 0.054904"/>
    <parent link="gripper_base"/>
    <child link="gripper_left_driver"/>
    <axis xyz="1 0 0"/>
    <limit effort="60" lower="0.0" upper="0.872664444444" velocity="1.91986177778"/>
    <!-- <limit effort="176" lower="0.0" upper="0.715584844444" velocity="1.91986177778"/>-->
    <mimic joint="gripper_right_driver_joint" multiplier="1"/>
  </joint>
  <link name="gripper_left_driver">
    <!-- inertial>
				<mass value="0.1"/>
				<origin xyz="0 0 0.055"  />
				<cylinder_inertia radius="0.06" length="0.11" mass="0.1"/>
			</inertial -->
    <visual>
      <geometry>
        <mesh filename="robotiq/visual/driver.dae" scale="0.001 0.001 0.001"/>
      </geometry>
    </visual>
    <collision>
      <origin rpy="-0.1 0 0" xyz="0 0.02 0"/>
      <geometry>
        <box size="0.02 0.04 0.02"/>
      </geometry>
    </collision>
  </link>
  <joint name="gripper_left_coupler_joint" type="fixed">
    <origin rpy="0 0 0" xyz="0 0.0315 -0.0041"/>
    <parent link="gripper_left_driver"/>
    <child link="gripper_left_coupler"/>
  </joint>
  <link name="gripper_left_coupler">
    <!-- inertial>
				<mass value="0.1"/>
				<origin xyz="0 0 0.055"  />
				<cylinder_inertia radius="0.06" length="0.11" mass="0.1"/>
			</inertial -->
    <visual>
      <geometry>
        <mesh filename="robotiq/visual/coupler.dae" scale="0.001 0.001 0.001"/>
      </geometry>
    </visual>
    <collision>
      <!--<origin rpy="-1.7 0 0" xyz="0 0.0 0.025"/>-->
      <origin rpy="-1.7 0 0" xyz="0 0.005 0.025"/>
      <material name="green">
        <color rgba="0.05 0.95 0.05 1"/>
      </material>
      <geometry>
        <!--<box size="0.03 0.065 0.02"/>-->
        <box size="0.03 0.065 0.01"/>
      </geometry>
    </collision>
  </link>
  <joint name="gripper_left_follower_joint" type="revolute">
    <origin rpy="0 0 0" xyz="0 0.0061 0.0471"/>
    <parent link="gripper_left_coupler"/>
    <child link="gripper_left_follower"/>
    <axis xyz="1 0 0"/>
    <limit effort="176" lower="-2.96705911111" upper="2.96705911111" velocity="1.91986177778"/>
    <mimic joint="gripper_right_driver_joint" multiplier="-1"/>
  </joint>
  <link name="gripper_left_follower">
    <visual>
      <geometry>
        <mesh filename="robotiq/visual/follower.dae" scale="0.001 0.001 0.001"/>
      </geometry>
    </visual>
    <collision>
      <origin rpy="0 0 0" xyz="0 -0.016 0.022"/> 
      <!--<origin rpy="0 0 0" xyz="0 -0.018 0.022"/>--> 
     <material name="dark_blue">
        <color rgba="0.2 0.2 0.8 1"/>
      </material>
      <geometry>
        <box size="0.02 0.01 0.048"/>
        <!--<box size="0.02 0.015 0.048"/>-->
      </geometry>
    </collision>
  </link>
  <joint name="gripper_left_pad_joint" type="fixed">
    <parent link="gripper_left_follower"/>
    <child link="gripper_left_pad"/>
  </joint>
  <link name="gripper_left_pad">
    <!-- inertial>
				<mass value="0.1"/>
				<origin xyz="0 0 0.055"  />
				<cylinder_inertia radius="0.06" length="0.11" mass="0.1"/>
			</inertial -->
    <visual>
      <geometry>
        <mesh filename="robotiq/visual/pad.dae" scale="0.001 0.001 0.001"/>
      </geometry>
    </visual>
    <collision>
      <origin rpy="0 0 0" xyz="0 -0.022 0.031"/>
      <material name="dark_gray">
        <color rgba="0.2 0.2 0.2 1"/>
      </material>
      <geometry>
        <box size="0.02 0.004 0.036"/>
        <!--<box size="0.02 0.008 0.036"/>-->
      </geometry>
    </collision>
  </link>
  <joint name="gripper_left_spring_link_joint" type="revolute">
    <origin rpy="0 0 3.141592653589793" xyz="0 -0.012 0.0614"/>
    <parent link="gripper_base"/>
    <child link="gripper_left_spring_link"/>
    <axis xyz="1 0 0"/>
    <limit effort="176" lower="-2.96705911111" upper="2.96705911111" velocity="1.91986177778"/>
    <mimic joint="gripper_right_driver_joint" multiplier="1"/>
  </joint>
  <link name="gripper_left_spring_link">
    <!-- inertial>
				<mass value="0.1"/>
				<origin xyz="0 0 0.055"  />
				<cylinder_inertia radius="0.06" length="0.11" mass="0.1"/>
			</inertial -->
    <visual>
      <geometry>
        <mesh filename="robotiq/visual/spring_link.dae" scale="0.001 0.001 0.001"/>
      </geometry>
    </visual>
    <collision>
      <origin rpy="-0.7068 0 0" xyz="0 0.018 0.018"/>
      <material name="red">
        <color rgba="0.95 0.05 0.05 1"/>
      </material>
      <geometry>
        <box size="0.04 0.01 0.045"/>
        <!--<box size="0.04 0.02 0.065"/>-->
      </geometry>
    </collision>
  </link>
</robot>

