<?xml version="1.0" encoding="utf-8"?>
  
<robot name="ur3_robotniq_A">
  <!-- ROS base_link to UR 'Base' Coordinates transform -->
  <!-- <link name="base"/>-->
 <!--  <joint name="base_link-base_fixed_joint" type="fixed">-->
    <!-- NOTE: this rotation is only needed as long as base_link itself is
                 not corrected wrt the real robot (ie: rotated over 180
                 degrees)
      -->
   <!--  <origin rpy="0 0 -3.14159265359" xyz="0 0 0"/>-->
    <!-- <parent link="base_link"/>-->
   <!--  <child link="base"/>-->
  <!-- </joint>-->

  <link name="base_link">
    <visual>
      <geometry>
        <mesh filename="UR3/visual/base.dae"/>
        <!--mesh filename="package://kautham/demos/models/robots/UR3/visual/base.dae"/-->
      </geometry>
      <material name="LightGrey">
        <color rgba="0.7 0.7 0.7 1.0"/>
      </material>
    </visual>
    <collision>
      <geometry>
        <mesh filename="UR3/collision/base.stl"/>
      </geometry>
    </collision>
    <inertial>
      <mass value="2.0"/>
      <origin rpy="0 0 0" xyz="0.0 0.0 0.0"/>
      <inertia ixx="0.0030531654454" ixy="0.0" ixz="0.0" iyy="0.0030531654454" iyz="0.0" izz="0.005625"/>
    </inertial>
  </link>
  <joint name="shoulder_pan_joint" type="revolute">
    <parent link="base_link"/>
    <child link="shoulder_link"/>
    <origin rpy="0.0 0.0 0.0" xyz="0.0 0.0 0.1519"/>
    <axis xyz="0 0 1"/>
    <limit effort="330.0" lower="-3.141592654" upper="3.141592654" velocity="2.16"/>
    <dynamics damping="0.0" friction="0.0"/>
  </joint>
  <link name="shoulder_link">
    <visual>
      <geometry>
        <mesh filename="UR3/visual/shoulder.dae"/>
      </geometry>
      <material name="LightGrey">
        <color rgba="0.7 0.7 0.7 1.0"/>
      </material>
    </visual>
    <collision>
      <geometry>
        <mesh filename="UR3/collision/shoulder.stl"/>
      </geometry>
    </collision>
    <inertial>
      <mass value="2.0"/>
      <origin rpy="0 0 0" xyz="0.0 0.0 0.0"/>
      <inertia ixx="0.0080931634294" ixy="0.0" ixz="0.0" iyy="0.0080931634294" iyz="0.0" izz="0.005625"/>
    </inertial>
  </link>
  <joint name="shoulder_lift_joint" type="revolute">
    <parent link="shoulder_link"/>
    <child link="upper_arm_link"/>
    <origin rpy="0.0 1.57079632679 0.0" xyz="0.0 0.1198 0.0"/>
    <axis xyz="0 1 0"/>
    <limit effort="330.0" lower="-3.141592654" upper="3.141592654" velocity="2.16"/>
    <dynamics damping="0.0" friction="0.0"/>
  </joint>
  <link name="upper_arm_link">
    <visual>
      <geometry>
        <mesh filename="UR3/visual/upperarm.dae"/>
      </geometry>
      <material name="LightGrey">
        <color rgba="0.7 0.7 0.7 1.0"/>
      </material>
    </visual>
    <collision>
      <geometry>
        <mesh filename="UR3/collision/upperarm.stl"/>
      </geometry>
    </collision>
    <inertial>
      <mass value="3.42"/>
      <origin rpy="0 0 0" xyz="0.0 0.0 0.121825"/>
      <inertia ixx="0.0217284832211" ixy="0.0" ixz="0.0" iyy="0.0217284832211" iyz="0.0" izz="0.00961875"/>
    </inertial>
  </link>
  <joint name="elbow_joint" type="revolute">
    <parent link="upper_arm_link"/>
    <child link="forearm_link"/>
    <origin rpy="0.0 0.0 0.0" xyz="0.0 -0.0925 0.24365"/>
    <axis xyz="0 1 0"/>
    <limit effort="150.0" lower="-3.14159265359" upper="3.14159265359" velocity="3.15"/>
    <dynamics damping="0.0" friction="0.0"/>
  </joint>
  <link name="forearm_link">
    <visual>
      <geometry>
        <mesh filename="UR3/visual/forearm.dae"/>
      </geometry>
      <material name="LightGrey">
        <color rgba="0.7 0.7 0.7 1.0"/>
      </material>
    </visual>
    <collision>
      <geometry>
        <mesh filename="UR3/collision/forearm.stl"/>
      </geometry>
    </collision>
    <inertial>
      <mass value="1.26"/>
      <origin rpy="0 0 0" xyz="0.0 0.0 0.106625"/>
      <inertia ixx="0.00654680644378" ixy="0.0" ixz="0.0" iyy="0.00654680644378" iyz="0.0" izz="0.00354375"/>
    </inertial>
  </link>
  <joint name="wrist_1_joint" type="revolute">
    <parent link="forearm_link"/>
    <child link="wrist_1_link"/>
    <origin rpy="0.0 1.57079632679 0.0" xyz="0.0 0.0 0.21325"/>
    <axis xyz="0 1 0"/>
    <limit effort="54.0" lower="-3.141592654" upper="3.141592654" velocity="3.2"/>
    <dynamics damping="0.0" friction="0.0"/>
  </joint>
  <link name="wrist_1_link">
    <visual>
      <geometry>
        <mesh filename="UR3/visual/wrist1.dae"/>
      </geometry>
      <material name="LightGrey">
        <color rgba="0.7 0.7 0.7 1.0"/>
      </material>
    </visual>
    <collision>
      <geometry>
        <mesh filename="UR3/collision/wrist1.stl"/>
      </geometry>
    </collision>
    <inertial>
      <mass value="0.8"/>
      <origin rpy="0 0 0" xyz="0.0 0.0 0.0"/>
      <inertia ixx="0.002084999166" ixy="0.0" ixz="0.0" iyy="0.002084999166" iyz="0.0" izz="0.00225"/>
    </inertial>
  </link>
  <joint name="wrist_2_joint" type="revolute">
    <parent link="wrist_1_link"/>
    <child link="wrist_2_link"/>
    <origin rpy="0.0 0.0 0.0" xyz="0.0 0.08505 0.0"/>
    <axis xyz="0 0 1"/>
    <limit effort="54.0" lower="-3.141592654" upper="3.141592654" velocity="3.2"/>
    <dynamics damping="0.0" friction="0.0"/>
  </joint>
  <link name="wrist_2_link">
    <visual>
      <geometry>
        <mesh filename="UR3/visual/wrist2.dae"/>
      </geometry>
      <material name="LightGrey">
        <color rgba="0.7 0.7 0.7 1.0"/>
      </material>
    </visual>
    <collision>
      <geometry>
        <mesh filename="UR3/collision/wrist2.stl"/>
      </geometry>
    </collision>
    <inertial>
      <mass value="0.8"/>
      <origin rpy="0 0 0" xyz="0.0 0.0 0.0"/>
      <inertia ixx="0.002084999166" ixy="0.0" ixz="0.0" iyy="0.002084999166" iyz="0.0" izz="0.00225"/>
    </inertial>
  </link>
  <joint name="wrist_3_joint" type="revolute">
    <parent link="wrist_2_link"/>
    <child link="wrist_3_link"/>
    <origin rpy="0.0 0.0 0.0" xyz="0.0 0.0 0.08535"/>
    <axis xyz="0 1 0"/>
    <limit effort="54.0" lower="-3.141592654" upper="3.141592654" velocity="3.2"/>
    <dynamics damping="0.0" friction="0.0"/>
  </joint>
  <link name="wrist_3_link">
    <visual>
      <geometry>
        <mesh filename="UR3/visual/wrist3.dae"/>
      </geometry>
      <material name="LightGrey">
        <color rgba="0.7 0.7 0.7 1.0"/>
      </material>
    </visual>
    <collision>
      <geometry>
        <mesh filename="UR3/collision/wrist3.stl"/>
      </geometry>
    </collision>
    <inertial>
      <mass value="0.35"/>
      <origin rpy="0 0 0" xyz="0.0 0.0 0.0"/>
      <inertia ixx="0.000912187135125" ixy="0.0" ixz="0.0" iyy="0.000912187135125" iyz="0.0" izz="0.000984375"/>
    </inertial>
  </link>

  <joint name="ee_fixed_joint" type="fixed">
    <parent link="wrist_3_link"/>
    <child link="ee_link"/>
    <origin rpy="0.0 0.0 1.57079632679" xyz="0.0 0.0819 0.0"/>
  </joint>
  <link name="ee_link">
    <visual>     
      <material name="LightGrey">
        <color rgba="0.7 0.7 0.7 1.0"/>
      </material>
      <geometry>
        <box size="0.01 0.01 0.01"/>
      </geometry>
      <origin rpy="0 0 0" xyz="-0.01 0 0"/>
    </visual>
    <collision>
      <geometry>
        <box size="0.01 0.01 0.01"/>
      </geometry>
      <origin rpy="0 0 0" xyz="-0.01 0 0"/>
    </collision>
  </link>
  




<!-- Frame coincident with all-zeros TCP on UR controller -->
  <link name="tool0">
    <visual>     
      <material name="LightGrey">
        <color rgba="0.7 0.7 0.7 1.0"/>
      </material>
      <geometry>
        <box size="0.01 0.01 0.01"/>
      </geometry>
      <origin rpy="0 0 0" xyz="-0.01 0 0"/>
    </visual>
    <collision>
      <origin rpy="0 0 0" xyz="0 0 -0.01"/>
      <geometry>
        <box size="0.01 0.01 0.001"/>
      </geometry>
      <material name="red">
        <color rgba="0.95 0.05 0.05 1"/>
      </material>
      <origin rpy="0 0 0" xyz="-0.01 0 0"/>
    </collision>
  </link>

  <joint name="wrist_3_link-tool0_fixed_joint" type="fixed">
    <origin rpy="-1.57079632679 0 0" xyz="0 0.0819 0"/>
    <parent link="wrist_3_link"/>
    <child link="tool0"/>
  </joint>
  <!-- Robotiq/UR coupler -->
  <joint name="coupler_joint" type="fixed">
    <parent link="tool0"/>
    <child link="coupler_link"/>
    <origin rpy="0.0 0.0 0.0" xyz="0.0 0.0 0.0"/>
  </joint>
  <link name="coupler_link">
    <visual>
      <!-- total height of coupler, minus the depth of robot end-effector shape-->
      <origin rpy="0 0 0" xyz="0 0 0.00545"/>
      <geometry>
        <cylinder length="0.0139" radius="0.0375"/>
      </geometry>
      <material name="dark_grey">
        <color rgba="0.05 0.05 0.05 1"/>
      </material>
    </visual>
    <collision>
      <origin rpy="0 0 0" xyz="0 0 0.01"/>
      <!--<origin rpy="0 0 0" xyz="0 0 0"/>-->
      <geometry>
        <cylinder length="0.0139" radius="0.0375"/>
      </geometry>
    </collision>
  </link>
  <!-- base -->
  <joint name="coupler_link_gripper_base_joint" type="fixed">
    <origin rpy="0 0 1.57079632679" xyz="0 0 0.0079"/>
    <parent link="coupler_link"/>
    <child link="gripper_base"/>
  </joint>
  <link name="gripper_base">
    <!-- inertial>
				<mass value="0.1"/>
				<origin xyz="0 0 0.055"  />
				<cylinder_inertia radius="0.06" length="0.11" mass="0.1"/>
			</inertial -->
    <visual>
      <geometry>
        <mesh filename="robotiq/visual/base.dae" scale="0.001 0.001 0.001"/>
      </geometry>
    </visual>
    <collision>
      <origin rpy="0 0 0" xyz="0 0 0.015"/>
      <geometry>
          <!--<cylinder length="0.045" radius="0.04"/>-->
        <cylinder length="0.045" radius="0.039"/>
      </geometry>
    </collision>
    <collision>
      <origin rpy="0 0 0" xyz="0 0 0.06"/>
      <geometry>
        <box size="0.03 0.04 0.06"/>
      </geometry>
    </collision>
  </link>



  <!-- right finger -->
  <joint name="gripper_right_driver_joint" type="revolute">
    <origin rpy="0 0 0" xyz="0 0.0306011 0.054904"/>
    <parent link="gripper_base"/>
    <child link="gripper_right_driver"/>
    <axis xyz="1 0 0"/>
    <limit effort="60" lower="0.0" upper="0.872664444444" velocity="1.91986177778"/>
  </joint>
  <link name="gripper_right_driver">
    <!-- inertial>
				<mass value="0.1"/>
				<origin xyz="0 0 0.055"  />
				<cylinder_inertia radius="0.06" length="0.11" mass="0.1"/>
			</inertial -->
    <visual>
      <geometry>
        <mesh filename="robotiq/visual/driver.dae" scale="0.001 0.001 0.001"/>
      </geometry>
    </visual>
    <collision>
      <origin rpy="-0.1 0 0" xyz="0 0.02 0"/>

      <geometry>
        <box size="0.02 0.04 0.02"/>
      </geometry>
    </collision>
  </link>
 

 <joint name="gripper_right_coupler_joint" type="fixed">
    <origin rpy="0 0 0" xyz="0 0.0315 -0.0041"/>
    <parent link="gripper_right_driver"/>
    <child link="gripper_right_coupler"/>
  </joint>
  <link name="gripper_right_coupler">
    <!-- inertial>
				<mass value="0.1"/>
				<origin xyz="0 0 0.055"  />
				<cylinder_inertia radius="0.06" length="0.11" mass="0.1"/>
			</inertial -->
    <visual>
      <geometry>
        <mesh filename="robotiq/visual/coupler.dae" scale="0.001 0.001 0.001"/>
      </geometry>
    </visual>
    <collision>
      <!--<origin rpy="-1.7 0 0" xyz="0 0.0 0.025"/>-->
      <origin rpy="-1.7 0 0" xyz="0 0.005 0.025"/>
      <material name="green">
        <color rgba="0.05 0.95 0.05 1"/>
      </material>
      <geometry>
        <!--<box size="0.03 0.065 0.02"/>-->
        <box size="0.03 0.065 0.01"/>
      </geometry>
    </collision>
  </link>
  

<joint name="gripper_right_follower_joint" type="revolute">
    <origin rpy="0 0 0" xyz="0 0.0061 0.0471"/>
    <parent link="gripper_right_coupler"/>
    <child link="gripper_right_follower"/>
    <axis xyz="1 0 0"/>
    <limit effort="176" lower="-2.96705911111" upper="2.96705911111" velocity="1.91986177778"/>
    <mimic joint="gripper_right_driver_joint" multiplier="-1"/>
  </joint>
  <link name="gripper_right_follower">
    <visual>
      <geometry>
        <mesh filename="robotiq/visual/follower.dae" scale="0.001 0.001 0.001"/>
      </geometry>
    </visual>
    <collision>
      <origin rpy="0 0 0" xyz="0 -0.016 0.022"/> 
      <!--<origin rpy="0 0 0" xyz="0 -0.018 0.022"/>--> 
     <material name="dark_blue">
        <color rgba="0.2 0.2 0.8 1"/>
      </material>
      <geometry>
        <box size="0.02 0.01 0.048"/>
        <!--<box size="0.02 0.015 0.048"/>-->
      </geometry>
    </collision>
  </link>
 

 <joint name="gripper_right_pad_joint" type="fixed">
    <parent link="gripper_right_follower"/>
    <child link="gripper_right_pad"/>
  </joint>
  <link name="gripper_right_pad">
    <!-- inertial>
				<mass value="0.1"/>
				<origin xyz="0 0 0.055"  />
				<cylinder_inertia radius="0.06" length="0.11" mass="0.1"/>
			</inertial -->
    <visual>
      <geometry>
        <mesh filename="robotiq/visual/pad.dae" scale="0.001 0.001 0.001"/>
      </geometry>
    </visual>
    <collision>
      <origin rpy="0 0 0" xyz="0 -0.022 0.031"/>
      <material name="dark_gray">
        <color rgba="0.2 0.2 0.2 1"/>
      </material>
      <geometry>
        <box size="0.02 0.004 0.036"/>
        <!--<box size="0.02 0.008 0.036"/>-->
      </geometry>
    </collision>
  </link>
  

<joint name="gripper_right_spring_link_joint" type="revolute">
    <origin rpy="0 0 0" xyz="0 0.012 0.0614"/>
    <parent link="gripper_base"/>
    <child link="gripper_right_spring_link"/>
    <axis xyz="1 0 0"/>
    <limit effort="176" lower="-2.96705911111" upper="2.96705911111" velocity="1.91986177778"/>
    <mimic joint="gripper_right_driver_joint" multiplier="1"/>
  </joint>
  <link name="gripper_right_spring_link">
    <!-- inertial>
				<mass value="0.1"/>
				<origin xyz="0 0 0.055"  />
				<cylinder_inertia radius="0.06" length="0.11" mass="0.1"/>
			</inertial -->
    <visual>
      <geometry>
        <mesh filename="robotiq/visual/spring_link.dae" scale="0.001 0.001 0.001"/>
      </geometry>
    </visual>
    <collision>
      <origin rpy="-0.7068 0 0" xyz="0 0.018 0.018"/>
      <material name="red">
        <color rgba="0.95 0.05 0.05 1"/>
      </material>
      <geometry>
        <box size="0.04 0.01 0.045"/>
        <!--<box size="0.04 0.02 0.065"/>-->
      </geometry>
    </collision>
  </link>








  <!-- left finger -->
  <joint name="gripper_left_driver_joint" type="revolute">
    <origin rpy="0 0 3.141592653589793" xyz="0 -0.0306011 0.054904"/>
    <parent link="gripper_base"/>
    <child link="gripper_left_driver"/>
    <axis xyz="1 0 0"/>
    <limit effort="60" lower="0.0" upper="0.872664444444" velocity="1.91986177778"/>
    <!-- <limit effort="176" lower="0.0" upper="0.715584844444" velocity="1.91986177778"/>-->
    <mimic joint="gripper_right_driver_joint" multiplier="1"/>
  </joint>
  <link name="gripper_left_driver">
    <!-- inertial>
				<mass value="0.1"/>
				<origin xyz="0 0 0.055"  />
				<cylinder_inertia radius="0.06" length="0.11" mass="0.1"/>
			</inertial -->
    <visual>
      <geometry>
        <mesh filename="robotiq/visual/driver.dae" scale="0.001 0.001 0.001"/>
      </geometry>
    </visual>
    <collision>
      <origin rpy="-0.1 0 0" xyz="0 0.02 0"/>
      <geometry>
        <box size="0.02 0.04 0.02"/>
      </geometry>
    </collision>
  </link>
  <joint name="gripper_left_coupler_joint" type="fixed">
    <origin rpy="0 0 0" xyz="0 0.0315 -0.0041"/>
    <parent link="gripper_left_driver"/>
    <child link="gripper_left_coupler"/>
  </joint>
  <link name="gripper_left_coupler">
    <!-- inertial>
				<mass value="0.1"/>
				<origin xyz="0 0 0.055"  />
				<cylinder_inertia radius="0.06" length="0.11" mass="0.1"/>
			</inertial -->
    <visual>
      <geometry>
        <mesh filename="robotiq/visual/coupler.dae" scale="0.001 0.001 0.001"/>
      </geometry>
    </visual>
    <collision>
      <!--<origin rpy="-1.7 0 0" xyz="0 0.0 0.025"/>-->
      <origin rpy="-1.7 0 0" xyz="0 0.005 0.025"/>
      <material name="green">
        <color rgba="0.05 0.95 0.05 1"/>
      </material>
      <geometry>
        <!--<box size="0.03 0.065 0.02"/>-->
        <box size="0.03 0.065 0.01"/>
      </geometry>
    </collision>
  </link>
  <joint name="gripper_left_follower_joint" type="revolute">
    <origin rpy="0 0 0" xyz="0 0.0061 0.0471"/>
    <parent link="gripper_left_coupler"/>
    <child link="gripper_left_follower"/>
    <axis xyz="1 0 0"/>
    <limit effort="176" lower="-2.96705911111" upper="2.96705911111" velocity="1.91986177778"/>
    <mimic joint="gripper_right_driver_joint" multiplier="-1"/>
  </joint>
  <link name="gripper_left_follower">
    <visual>
      <geometry>
        <mesh filename="robotiq/visual/follower.dae" scale="0.001 0.001 0.001"/>
      </geometry>
    </visual>
    <collision>
      <origin rpy="0 0 0" xyz="0 -0.016 0.022"/> 
      <!--<origin rpy="0 0 0" xyz="0 -0.018 0.022"/>--> 
     <material name="dark_blue">
        <color rgba="0.2 0.2 0.8 1"/>
      </material>
      <geometry>
        <box size="0.02 0.01 0.048"/>
        <!--<box size="0.02 0.015 0.048"/>-->
      </geometry>
    </collision>
  </link>
  <joint name="gripper_left_pad_joint" type="fixed">
    <parent link="gripper_left_follower"/>
    <child link="gripper_left_pad"/>
  </joint>
  <link name="gripper_left_pad">
    <!-- inertial>
				<mass value="0.1"/>
				<origin xyz="0 0 0.055"  />
				<cylinder_inertia radius="0.06" length="0.11" mass="0.1"/>
			</inertial -->
    <visual>
      <geometry>
        <mesh filename="robotiq/visual/pad.dae" scale="0.001 0.001 0.001"/>
      </geometry>
    </visual>
    <collision>
      <origin rpy="0 0 0" xyz="0 -0.022 0.031"/>
      <material name="dark_gray">
        <color rgba="0.2 0.2 0.2 1"/>
      </material>
      <geometry>
        <box size="0.02 0.004 0.036"/>
        <!--<box size="0.02 0.008 0.036"/>-->
      </geometry>
    </collision>
  </link>
  <joint name="gripper_left_spring_link_joint" type="revolute">
    <origin rpy="0 0 3.141592653589793" xyz="0 -0.012 0.0614"/>
    <parent link="gripper_base"/>
    <child link="gripper_left_spring_link"/>
    <axis xyz="1 0 0"/>
    <limit effort="176" lower="-2.96705911111" upper="2.96705911111" velocity="1.91986177778"/>
    <mimic joint="gripper_right_driver_joint" multiplier="1"/>
  </joint>
  <link name="gripper_left_spring_link">
    <!-- inertial>
				<mass value="0.1"/>
				<origin xyz="0 0 0.055"  />
				<cylinder_inertia radius="0.06" length="0.11" mass="0.1"/>
			</inertial -->
    <visual>
      <geometry>
        <mesh filename="robotiq/visual/spring_link.dae" scale="0.001 0.001 0.001"/>
      </geometry>
    </visual>
    <collision>
      <origin rpy="-0.7068 0 0" xyz="0 0.018 0.018"/>
      <material name="red">
        <color rgba="0.95 0.05 0.05 1"/>
      </material>
      <geometry>
        <box size="0.04 0.01 0.045"/>
        <!--<box size="0.04 0.02 0.065"/>-->
      </geometry>
    </collision>
  </link>





</robot>

