<?xml version="1.0" encoding="utf-8"?>
  
<robot name="ur3e_gripper_rg6">

    <link name="base_link">
        <visual>
            <geometry>
                <mesh filename="UR3e/visual/base.dae"/>
            </geometry>
            <material name="LightGrey">
                <color rgba="0.7 0.7 0.7 1.0"/>
            </material>
        </visual>
        <collision>
            <geometry>
                <mesh filename="UR3e/collision/base.stl"/>
            </geometry>
        </collision>
    </link>

    <joint name="shoulder_pan_joint" type="revolute">
        <parent link="base_link"/>
        <child link="shoulder_link"/>
        <origin xyz="0.0 0.0 0.15185" rpy="0.0 0.0 0.0"/>
        <axis xyz="0 0 1"/>
        <limit effort="54.0" lower="-6.28" upper="6.28" velocity="3.14"/>
        <dynamics damping="0.0" friction="0.0"/>
    </joint>

    <link name="shoulder_link">
        <visual>
            <origin xyz="0 0 0" rpy="0 0 3.14"/>
            <geometry>
                <mesh filename="UR3e/visual/shoulder.dae"/>
            </geometry>
            <material name="LightGrey">
                <color rgba="0.7 0.7 0.7 1.0"/>
            </material>
        </visual>
        <collision>
            <origin xyz="0 0 0" rpy="0 0 3.14"/>
            <geometry>
                <mesh filename="UR3e/collision/shoulder.stl"/>
            </geometry>
        </collision>
        <inertial>
            <mass value="1.98"/>
            <origin rpy="0 0 0" xyz="0.0 0.0 -0.02"/>
            <inertia ixx="0.008093166666666665" ixy="0.0" ixz="0.0" iyy="0.008093166666666665" iyz="0.0" izz="0.005625"/>
        </inertial>
    </link>

    <joint name="shoulder_lift_joint" type="revolute">
        <parent link="shoulder_link"/>
        <child link="upper_arm_link"/>
        <origin xyz="0.0 0.0 0.0" rpy="1.570796327 0.0 0.0"/>
        <axis xyz="0 0 1"/>
        <limit effort="54.0" lower="-6.28" upper="6.28" velocity="3.14"/>
        <dynamics damping="0.0" friction="0.0"/>
    </joint>

    <link name="upper_arm_link">
        <visual>
            <origin xyz="0 0 0.120" rpy="1.570796 0 -1.570796"/>
            <geometry>
                <mesh filename="UR3e/visual/upperarm.dae"/>
            </geometry>
            <material name="LightGrey">
                <color rgba="0.7 0.7 0.7 1.0"/>
            </material>
        </visual>
        <collision>
            <origin xyz="0 0 0.120" rpy="1.570796 0 -1.570796"/>
            <geometry>
                <mesh filename="UR3e/collision/upperarm.stl"/>
            </geometry>
        </collision>
        <inertial>
            <mass value="3.4445"/>
            <origin rpy="0 0 0" xyz="-0.11355 0.0 0.1157"/>
            <inertia ixx="0.021728491912499998" ixy="0.0" ixz="0.0" iyy="0.021728491912499998" iyz="0.0" izz="0.00961875"/>
        </inertial>
    </link>

    <joint name="elbow_joint" type="revolute">
        <parent link="upper_arm_link"/>
        <child link="forearm_link"/>
        <origin xyz="-0.24355 0.0 0.0" rpy="0.0 0.0 0.0"/>
        <axis xyz="0 0 1"/>
        <limit effort="28.0" lower="-3.14" upper="3.14" velocity="3.14"/>
        <dynamics damping="0.0" friction="0.0"/>
    </joint>

    <link name="forearm_link">
        <visual>
            <origin xyz="0 0 0.027" rpy="1.570796 0 -1.570796"/>
            <geometry>
                <mesh filename="UR3e/visual/forearm.dae"/>
            </geometry>
            <material name="LightGrey">
                <color rgba="0.7 0.7 0.7 1.0"/>
            </material>
        </visual>
        <collision>
            <origin xyz="0 0 0.027" rpy="1.570796 0 -1.570796"/>
            <geometry>
                <mesh filename="UR3e/collision/forearm.stl"/>
            </geometry>
        </collision>
        <inertial>
            <mass value="1.437"/>
            <origin rpy="0 0 0" xyz="-0.1632 0.0 0.0238"/>
            <inertia ixx="0.006544570199999999" ixy="0.0" ixz="0.0" iyy="0.006544570199999999" iyz="0.0" izz="0.00354375"/>
        </inertial>
    </link>

    <joint name="wrist_1_joint" type="revolute">
        <parent link="forearm_link"/>
        <child link="wrist_1_link"/>
        <origin xyz="-0.2132 0.0 0.13105" rpy="0.0 0.0 0.0"/>
        <axis xyz="0 0 1"/>
        <limit effort="9.0" lower="-6.28" upper="6.28" velocity="6.28"/>
        <dynamics damping="0.0" friction="0.0"/>
    </joint>

    <link name="wrist_1_link">
        <visual>
            <origin xyz="0 0 -0.104" rpy="1.570796 0 0"/>
            <geometry>
                <mesh filename="UR3e/visual/wrist1.dae"/>
            </geometry>
            <material name="LightGrey">
                <color rgba="0.7 0.7 0.7 1.0"/>
            </material>
        </visual>
        <collision>
            <origin xyz="0 0 -0.104" rpy="1.570796 0 0"/>
            <geometry>
                <mesh filename="UR3e/collision/wrist1.stl"/>
            </geometry>
        </collision>
        <inertial>
            <mass value="0.871"/>
            <origin rpy="0 0 0" xyz="0.0 -0.01 0.0"/>
            <inertia ixx="0.0020849999999999996" ixy="0.0" ixz="0.0" iyy="0.0020849999999999996" iyz="0.0" izz="0.00225"/>
        </inertial>
    </link>

    <joint name="wrist_2_joint" type="revolute">
        <parent link="wrist_1_link"/>
        <child link="wrist_2_link"/>
        <origin xyz="0.0 -0.08535 -1.750557762378351e-11" rpy="1.570796327 0.0 0.0"/>
        <axis xyz="0 0 1"/>
        <limit effort="9.0" lower="-6.28" upper="6.28" velocity="6.28"/>
        <dynamics damping="0.0" friction="0.0"/>
    </joint>

    <link name="wrist_2_link">
        <visual>
            <origin xyz="0 0 -0.08535" rpy="0 0 0"/>
            <geometry>
                <mesh filename="UR3e/visual/wrist2.dae"/>
            </geometry>
            <material name="LightGrey">
                <color rgba="0.7 0.7 0.7 1.0"/>
            </material>
        </visual>
        <collision>
            <origin xyz="0 0 -0.08535" rpy="0 0 0"/>
            <geometry>
                <mesh filename="UR3e/collision/wrist2.stl"/>
            </geometry>
        </collision>
        <inertial>
            <mass value="0.805"/>
            <origin rpy="0 0 0" xyz="0.0 0.01 0.0"/>
            <inertia ixx="0.0020849999999999996" ixy="0.0" ixz="0.0" iyy="0.0020849999999999996" iyz="0.0" izz="0.00225"/>
        </inertial>
    </link>

    <joint name="wrist_3_joint" type="revolute">
        <parent link="wrist_2_link"/>
        <child link="wrist_3_link"/>
        <origin xyz="0.0 0.0921 -1.8890025766262e-11" rpy="1.570796326589793 3.141592653589793 3.141592653589793"/>
        <axis xyz="0 0 1"/>
        <limit effort="9.0" lower="-6.28" upper="6.28" velocity="6.28"/>
        <dynamics damping="0.0" friction="0.0"/>
    </joint>

    <link name="wrist_3_link">
        <visual>
            <origin xyz="0 0 -0.0921" rpy="1.570796 0 0"/>
            <geometry>
                <mesh filename="UR3e/visual/wrist3.dae"/>
            </geometry>
            <material name="LightGrey">
                <color rgba="0.7 0.7 0.7 1.0"/>
            </material>
        </visual>
        <collision>
            <origin xyz="0 0 -0.0921" rpy="1.570796 0 0"/>
            <geometry>
                <mesh filename="UR3e/collision/wrist3.stl"/>
            </geometry>
        </collision>
        <inertial>
            <mass value="0.261"/>
            <origin rpy="0 0 0" xyz="0.0 0.0 -0.02"/>
            <inertia ixx="0.00013626666666666665" ixy="0.0" ixz="0.0" iyy="0.00013626666666666665" iyz="0.0" izz="0.0001792"/>
        </inertial>
    </link>


<!-- ################################### -->
<!-- ########### RG6 GRIPPER ########### -->
<!-- ################################### -->


    <material name="silver">
        <color rgba="0.700 0.700 0.700 1.000"/>
    </material>

    <joint name="wrist3_rg6_gripper" type="fixed">
        <origin xyz="0 0 0" rpy="0 0 0"/>
        <parent link="wrist_3_link"/>
        <child link="rg6_gripper_base_link"/>
    </joint>

    <link name="rg6_gripper_base_link">
        <inertial>
            <origin xyz="-0.00030179080386336256 -0.00047670368310389217 0.020678912231015475" rpy="0 0 0"/>
            <mass value="0.7592453895368185"/>
            <inertia ixx="0.000452" iyy="0.000705" izz="0.000689" ixy="-1e-06" iyz="-5e-06" ixz="-0.0"/>
        </inertial>
        <visual>
            <origin xyz="0 0 0" rpy="0 0 0"/>
            <geometry>
                <mesh filename="rg6_gripper/meshes/base_link.stl" scale="0.001 0.001 0.001"/>
            </geometry>
            <material name="silver"/>
        </visual>
        <collision>
            <origin xyz="0 0 0" rpy="0 0 0"/>
            <geometry>
                <mesh filename="rg6_gripper/meshes/base_link.stl" scale="0.001 0.001 0.001"/>
            </geometry>
        </collision>
    </link>

    <link name="g_main">
        <inertial>
            <origin xyz="0.031843851343412694 -6.562152034605188e-05 0.0402561266087614" rpy="0 0 0"/>
            <mass value="2.1746665575894286"/>
            <inertia ixx="0.003297" iyy="0.00361" izz="0.00105" ixy="-1e-06" iyz="5e-06" ixz="3e-06"/>
        </inertial>
        <visual>
            <origin xyz="0.031849 -1e-06 -0.04953" rpy="0 0 0"/>
            <geometry>
                <mesh filename="rg6_gripper/meshes/g_main.stl" scale="0.001 0.001 0.001"/>
            </geometry>
            <material name="silver"/>
        </visual>
        <collision>
            <origin xyz="0.031849 -1e-06 -0.04953" rpy="0 0 0"/>
            <geometry>
                <mesh filename="rg6_gripper/meshes/g_main.stl" scale="0.001 0.001 0.001"/>
            </geometry>
        </collision>
    </link>

    <link name="l_out">
        <inertial>
            <origin xyz="0.010442859349590227 -0.012799625869821 0.012792983853972317" rpy="0 0 0"/>
            <mass value="0.24195762212403002"/>
            <inertia ixx="0.00011" iyy="0.00016" izz="7.6e-05" ixy="0.0" iyz="0.0" ixz="-6.6e-05"/>
        </inertial>
        <visual>
            <origin xyz="-0.023851 -0.012801 -0.13453" rpy="0 0 0"/>
            <geometry>
                <mesh filename="rg6_gripper/meshes/l_out.stl" scale="0.001 0.001 0.001"/>
            </geometry>
            <material name="silver"/>
        </visual>
        <collision>
            <origin xyz="-0.023851 -0.012801 -0.13453" rpy="0 0 0"/>
            <geometry>
                <mesh filename="rg6_gripper/meshes/l_out.stl" scale="0.001 0.001 0.001"/>
            </geometry>
        </collision>
    </link>

    <link name="r_out">
        <inertial>
            <origin xyz="-0.010522665986501832 -0.012799489922871823 0.012809246687502496" rpy="0 0 0"/>
            <mass value="0.24195762035711757"/>
            <inertia ixx="0.00011" iyy="0.00016" izz="7.6e-05" ixy="0.0" iyz="-0.0" ixz="6.5e-05"/>
        </inertial>
        <visual>
            <origin xyz="0.023749 -0.012801 -0.13453" rpy="0 0 0"/>
            <geometry>
                <mesh filename="rg6_gripper/meshes/r_out.stl" scale="0.001 0.001 0.001"/>
            </geometry>
            <material name="silver"/>
        </visual>
        <collision>
            <origin xyz="0.023749 -0.012801 -0.13453" rpy="0 0 0"/>
            <geometry>
                <mesh filename="rg6_gripper/meshes/r_out.stl" scale="0.001 0.001 0.001"/>
            </geometry>
        </collision>
    </link>

    <link name="l_tip">
        <inertial>
            <origin xyz="-0.01379426979129901 0.012430443916766657 0.03303967984911002" rpy="0 0 0"/>
            <mass value="0.13426652162693567"/>
            <inertia ixx="5.6e-05" iyy="5.9e-05" izz="1.3e-05" ixy="-0.0" iyz="-0.0" ixz="1.6e-05"/>
        </inertial>
        <visual>
            <origin xyz="-0.071235 0.012499 -0.19895" rpy="0 0 0"/>
            <geometry>
                <mesh filename="rg6_gripper/meshes/l_tip.stl" scale="0.001 0.001 0.001"/>
            </geometry>
            <material name="silver"/>
        </visual>
        <collision>
            <origin xyz="-0.071235 0.012499 -0.19895" rpy="0 0 0"/>
            <geometry>
                <mesh filename="rg6_gripper/meshes/l_tip.stl" scale="0.001 0.001 0.001"/>
            </geometry>
        </collision>
    </link>

    <link name="r_tip">
        <inertial>
            <origin xyz="0.01379460286375201 0.012599371946431372 0.03303919214417522" rpy="0 0 0"/>
            <mass value="0.13426652162693592"/>
            <inertia ixx="5.6e-05" iyy="5.9e-05" izz="1.3e-05" ixy="-0.0" iyz="-0.0" ixz="-1.6e-05"/>
        </inertial>
        <visual>
            <origin xyz="0.071133 0.012499 -0.199024" rpy="0 0 0"/>
            <geometry>
                <mesh filename="rg6_gripper/meshes/r_tip.stl" scale="0.001 0.001 0.001"/>
            </geometry>
            <material name="silver"/>
        </visual>
        <collision>
            <origin xyz="0.071133 0.012499 -0.199024" rpy="0 0 0"/>
            <geometry>
                <mesh filename="rg6_gripper/meshes/r_tip.stl" scale="0.001 0.001 0.001"/>
            </geometry>
        </collision>
    </link>

    <!-- <link name="l_inner">
        <inertial>
            <origin xyz="0.021220873634115123 -0.00019955790008889003 0.02884270588361451" rpy="0 0 0"/>
            <mass value="0.0502402669834145"/>
            <inertia ixx="3.4e-05" iyy="4.6e-05" izz="2e-05" ixy="-0.0" iyz="-0.0" ixz="-2.2e-05"/>
        </inertial>
        <visual>
            <origin xyz="-0.010551 -0.000101 -0.15763" rpy="0 0 0"/>
            <geometry>
                <mesh filename="rg6_gripper/meshes/l_inner.stl" scale="0.001 0.001 0.001"/>
            </geometry>
            <material name="silver"/>
        </visual>
        <collision>
            <origin xyz="-0.010551 -0.000101 -0.15763" rpy="0 0 0"/>
            <geometry>
                <mesh filename="rg6_gripper/meshes/l_inner.stl" scale="0.001 0.001 0.001"/>
            </geometry>
        </collision>
    </link> -->

    <!-- <link name="r_inner">
        <inertial>
            <origin xyz="-0.021275767636285234 -0.00019955790008339296 0.02887567083082221" rpy="0 0 0"/>
            <mass value="0.05024026698344974"/>
            <inertia ixx="3.4e-05" iyy="4.6e-05" izz="2e-05" ixy="-0.0" iyz="0.0" ixz="2.2e-05"/>
        </inertial>
        <visual>
            <origin xyz="0.010449 -0.000101 -0.15763" rpy="0 0 0"/>
            <geometry>
                <mesh filename="rg6_gripper/meshes/r_inner.stl" scale="0.001 0.001 0.001"/>
            </geometry>
            <material name="silver"/>
        </visual>
        <collision>
            <origin xyz="0.010449 -0.000101 -0.15763" rpy="0 0 0"/>
            <geometry>
                <mesh filename="rg6_gripper/meshes/r_inner.stl" scale="0.001 0.001 0.001"/>
            </geometry>
        </collision>
    </link> -->

    <joint name="g_main" type="fixed">
        <origin xyz="-0.031849 1e-06 0.04953" rpy="0 0 0"/>
        <parent link="rg6_gripper_base_link"/>
        <child link="g_main"/>
    </joint>

    <joint name="l_out" type="revolute">
        <origin xyz="0.0557 0.0128 0.085" rpy="0 0 0"/>
        <parent link="g_main"/>
        <child link="l_out"/>
        <axis xyz="-0.0 1.0 0.0"/>
        <limit upper="0.610865" lower="-0.523599" effort="100" velocity="100"/>
    </joint>

    <joint name="r_out" type="revolute">
        <origin xyz="0.0081 0.0128 0.085" rpy="0 0 0"/>
        <parent link="g_main"/>
        <child link="r_out"/>
        <axis xyz="-0.0 1.0 0.0"/>
        <limit upper="0.523599" lower="-0.610865" effort="100" velocity="100"/>
        <mimic joint="l_out" multiplier="-1"/>
    </joint>

    <joint name="l_tip" type="revolute">
        <origin xyz="0.047384 -0.0253 0.06442" rpy="0 0 0"/>
        <parent link="l_out"/>
        <child link="l_tip"/>
        <axis xyz="0.0 -1.0 0.0"/>
        <limit upper="0.610865" lower="-0.523599" effort="100" velocity="100"/>
        <mimic joint="l_out" multiplier="1"/>
    </joint>

    <joint name="r_tip" type="revolute">
        <origin xyz="-0.047384 -0.0253 0.064494" rpy="0 0 0"/>
        <parent link="r_out"/>
        <child link="r_tip"/>
        <axis xyz="0.0 -1.0 0.0"/>
        <limit upper="0.523599" lower="-0.610865" effort="100" velocity="100"/>
        <mimic joint="l_out" multiplier="-1"/>
    </joint>

    <!-- <joint name="l_passive" type="revolute">
        <origin xyz="0.0424 0.0001 0.1081" rpy="0 0 0"/>
        <parent link="g_main"/>
        <child link="l_inner"/>
        <axis xyz="0.0 -1.0 0.0"/>
        <limit upper="0.523599" lower="-0.610865" effort="100" velocity="100"/>
        <mimic joint="l_out" multiplier="-1"/>
    </joint> -->

    <!-- <joint name="r_passive" type="revolute">
        <origin xyz="0.0214 0.0001 0.1081" rpy="0 0 0"/>
        <parent link="g_main"/>
        <child link="r_inner"/>
        <axis xyz="-0.0 1.0 -0.0"/>
        <limit upper="0.523599" lower="-0.610865" effort="100" velocity="100"/>
        <mimic joint="l_out" multiplier="-1"/>
    </joint> -->

    <!-- <link name="hand_tcp" /> -->
    <!-- <joint name="hand_tcp_joint" type="fixed">
        <origin xyz="0.036 0 0.21" rpy="0 0 0" />
        <parent link="g_main" />
        <child link="hand_tcp" />
        <axis xyz="-0.0 1.0 -0.0"/>
    </joint> -->


</robot>
