<?xml version="1.0" ?>
<robot name="UR5_AllegroHandL">
  <link name="Base">
    <visual>
      <origin rpy="0 0 0.785398163"/>
      <geometry>
        <mesh filename="UR5_DAE/visual/Base.dae"/>
      </geometry>
    </visual>
    <collision>
      <material name="grey">
        <color rgba="0.44 0.44 0.44 1"/>
      </material>
      <origin xyz="0 0 0.0055"/>
      <geometry>
         <cylinder radius="0.0745" length="0.017"/>
      </geometry>
    </collision>
    <inertial>
      <mass value="4"/>
      <inertia ixx="0.00443333156" ixy="0" ixz="0" iyy="0.00443333156" iyz="0" izz="0.0072"/>
    </inertial>
  </link>
  <joint name="ShoulderPanJoint" type="revolute">
    <parent link="Base"/>
    <child link="Shoulder"/>
    <origin xyz="0 0 0.089159" rpy="0 0 0.785398163"/>
    <axis xyz="0 0 1"/>
    <limit effort="150" lower="-6.2831853" upper="6.2831853" velocity="3.15"/>
  </joint>
  <link name="Shoulder">
    <visual>
      <geometry>
        <mesh filename="UR5_DAE/visual/Shoulder.dae"/>
      </geometry>
    </visual>
    <collision>
      <material name="black">
        <color rgba="0.09 0.09 0.09 1"/>
      </material>
      <origin xyz="0 0 -0.003"/>
      <geometry>
         <cylinder radius="0.0638" length="0.143"/>
      </geometry>
    </collision>
    <inertial>
      <mass value="3.7"/>
      <inertia ixx="0.010267495893" ixy="0" ixz="0" iyy="0.010267495893" iyz="0" izz="0.00666"/>
    </inertial>
  </link>
  <joint name="ShoulderLiftJoint" type="revolute">
    <parent link="Shoulder"/>
    <child link="UpperArm"/>
    <origin rpy="0 1.570796325 0" xyz="0 0.13585 0"/>
    <axis xyz="0 1 0"/>
    <limit effort="150" lower="-6.2831853" upper="6.2831853" velocity="3.15"/>
  </joint>
  <link name="UpperArm">
    <visual>
      <geometry>
        <mesh filename="UR5_DAE/visual/UpperArm.dae"/>
      </geometry>
    </visual>
    <collision>
      <material name="black"/>
      <origin xyz="0 -0.0336 0" rpy="1.570796327 0 0"/>
      <geometry>
         <cylinder radius="0.0638" length="0.2042"/>
      </geometry>
    </collision>
    <collision>
      <material name="grey"/>
      <origin xyz="0 0 0.2125"/>
      <geometry>
         <cylinder radius="0.0588" length="0.425"/>
      </geometry>
    </collision>
    <collision>
      <material name="black"/>
      <origin xyz="0 -0.0305 0.425" rpy="1.570796327 0 0"/>
      <geometry>
         <cylinder radius="0.0638" length="0.198"/>
      </geometry>
    </collision>
    <inertial>
      <mass value="8.393"/>
      <origin xyz="0 0 0.28"/>
      <inertia ixx="0.22689067591" ixy="0" ixz="0" iyy="0.22689067591" iyz="0" izz="0.0151074"/>
    </inertial>
  </link>
  <joint name="ElbowJoint" type="revolute">
    <parent link="UpperArm"/>
    <child link="ForeArm"/>
    <origin xyz="0 -0.1197 0.425"/>
    <axis xyz="0 1 0"/>
    <limit effort="150" lower="-6.2831853" upper="6.2831853" velocity="3.15"/>
  </joint>
  <link name="ForeArm">
    <visual>
      <geometry>
        <mesh filename="UR5_DAE/visual/Forearm.dae"/>
      </geometry>
    </visual>
    <collision>
      <material name="grey"/>
      <origin xyz="0 0 0.180"/>
      <geometry>
         <cylinder radius="0.0421" length="0.424"/>
      </geometry>
    </collision>
    <collision>
      <material name="black"/>
      <origin xyz="0 0.019 0.392" rpy="1.570796327 0 0"/>
      <geometry>
         <cylinder radius="0.0421" length="0.1524"/>
      </geometry>
    </collision>
    <inertial>
      <mass value="2.275"/>
      <origin xyz="0 0 0.25"/>
      <inertia ixx="0.049443313556" ixy="0" ixz="0" iyy="0.049443313556" iyz="0" izz="0.004095"/>
    </inertial>
  </link>
  <joint name="Wrist1Joint" type="revolute">
    <parent link="ForeArm"/>
    <child link="Wrist1"/>
    <origin rpy="0 1.570796325 0" xyz="0 0 0.39225"/>
    <axis xyz="0 1 0"/>
    <limit effort="28" lower="-6.2831853" upper="6.2831853" velocity="3.2"/>
  </joint>
  <link name="Wrist1">
    <visual>
      <geometry>
        <mesh filename="UR5_DAE/visual/Wrist1.dae"/>
      </geometry>
    </visual>
    <collision>
      <material name="black"/>
      <origin xyz="0 0.093 0.019"/>
      <geometry>
         <cylinder radius="0.0421" length="0.1524"/>
      </geometry>
    </collision>
    <inertial>
      <mass value="1.219"/>
      <inertia ixx="0.111172755531" ixy="0" ixz="0" iyy="0.111172755531" iyz="0" izz="0.21942"/>
    </inertial>
  </link>
  <joint name="Wrist2Joint" type="revolute">
    <parent link="Wrist1"/>
    <child link="Wrist2"/>
    <origin xyz="0 0.093 0"/>
    <axis xyz="0 0 1"/>
    <limit effort="28" lower="-6.2831853" upper="6.2831853" velocity="3.2"/>
  </joint>
  <link name="Wrist2">
    <visual>
      <geometry>
        <mesh filename="UR5_DAE/visual/Wrist2.dae"/>
      </geometry>
    </visual>
    <collision>
      <material name="black"/>
      <origin xyz="0 0.00885 0.09475" rpy="1.570796325 0 0"/>
      <geometry>
         <cylinder radius="0.0421" length="0.1321"/>
      </geometry>
    </collision>
    <inertial>
      <mass value="1.219"/>
      <inertia ixx="0.111172755531" ixy="0" ixz="0" iyy="0.111172755531" iyz="0" izz="0.21942"/>
    </inertial>
  </link>
  <joint name="Wrist3Joint" type="revolute">
    <parent link="Wrist2"/>
    <child link="Wrist3"/>
    <origin xyz="0 0 0.09465"/>
    <axis xyz="0 1 0"/>
    <limit effort="28" lower="-6.2831853" upper="6.2831853" velocity="3.2"/>
  </joint>
  <link name="Wrist3">
    <visual>
      <geometry>
        <mesh filename="UR5_DAE/visual/Wrist3.dae"/>
      </geometry>
    </visual>
    <collision>
      <material name="grey"/>
      <origin xyz="0 0.0784 0" rpy="1.570796325 0 0"/>
      <geometry>
         <cylinder radius="0.0319" length="0.007"/>
      </geometry>
    </collision>
    <inertial>
      <mass value="0.1879"/>
      <inertia ixx="0.0171364731454" ixy="0" ixz="0" iyy="0.0171364731454" iyz="0" izz="0.033822"/>
    </inertial>
  </link>
  <joint name="SupportJoint" type="fixed">
    <parent link="Wrist3"/>
    <child link="Support"/>
    <origin rpy="-1.570796325 0 0" xyz="0 0.1089 0"/>
  </joint>
  <link name="Support">
    <visual>
      <geometry>
        <mesh filename="UR5/AH_support.wrl" scale="0.001 0.001 0.001"/>
      </geometry>
    </visual>
    <collision>
      <material name="grey"/>
      <origin xyz="0 0 -0.0055" rpy="0 0 1.570796327"/>
      <geometry>
         <cylinder radius="0.0355" length="0.043"/>
      </geometry>
    </collision>
  </link>
  <joint name="PalmJoint" type="fixed">
    <parent link="Support"/>
    <child link="Palm"/>
    <origin rpy="0 0 1.570796327" xyz="0 0.009 0.111"/>
  </joint>
  <link name="Palm">
    <visual>
      <geometry>
	<mesh filename="AllegroHand/left/base_link_left.wrl" scale="0.001 0.001 0.001"/>
      </geometry>
    </visual>
    <collision>
      <material name="black"/>
	<origin xyz="-0.009300 0 -0.0475"/>
	<geometry>
	  <box size="0.0408 0.1130 0.095"/>
	</geometry>
    </collision>
  </link>
  <link name="Ring-base">
    <visual>
      <geometry>
        <mesh filename="AllegroHand/left/link_0_0.wrl" scale="0.001 0.001 0.001"/>
      </geometry>
      <origin xyz="0 0 0.0164"/>
    </visual>
    <collision>
      <material name="black"/>
      <geometry>
        <box size="0.0196 0.0275 0.0164"/>
      </geometry>
      <origin xyz="0 0 0.0082"/>
    </collision>
  </link>
  <joint name="joint_8.0" type="revolute">
      <axis xyz="0 0 1"/>
      <limit effort="1" lower="-0.47" upper="0.47" velocity="1"/>
      <parent link="Palm"/>
      <child link="Ring-base"/>
      <origin rpy="-0.08726646255 0 0" xyz="0 0.0435 -0.001542"/>
  </joint>
  <link name="Ring-proximal">
    <visual>
      <geometry>
        <mesh filename="AllegroHand/left/link_1_0.wrl" scale="0.001 0.001 0.001"/>
      </geometry>
      <origin rpy="1.5707963 -1.5707963 0"/>
    </visual>
    <collision>
      <material name="black"/>
      <geometry>
        <box size="0.0196 0.0275 0.054"/>
      </geometry>
      <origin xyz="0 0 0.027"/>
    </collision>
  </link>
  <joint name="joint_9.0" type="revolute">
      <limit effort="1" lower="-0.196" upper="1.61" velocity="1"/>
      <axis xyz="0 1 0"/>
      <parent link="Ring-base"/>
      <child link="Ring-proximal"/>
      <origin xyz="0 0 0.0164"/>
  </joint>
  <link name="Ring-distal">
    <visual>
      <geometry>
        <mesh filename="AllegroHand/left/link_2_0.wrl" scale="0.001 0.001 0.001"/>
      </geometry>
      <origin rpy="-1.5707963 -1.5707963 0"/>
    </visual>
    <collision>
      <material name="black"/>
      <geometry>
        <box size="0.0196 0.0275 0.0384"/>
      </geometry>
      <origin xyz="0 0 0.0192"/>
    </collision>
  </link>
  <joint name="joint_10.0" type="revolute">
      <axis xyz="0 1 0"/>
      <limit effort="1" lower="-0.174" upper="1.709" velocity="1"/>
      <parent link="Ring-proximal"/>
      <child link="Ring-distal"/>
      <origin xyz="0 0 0.054"/>
  </joint>
  <link name="Ring-last">
    <visual>
      <geometry>
        <mesh filename="AllegroHand/left/link_3_0.wrl" scale="0.001 0.001 0.001"/>
      </geometry>
      <origin rpy="-1.5707963 -1.5707963 0"/>
    </visual>
    <collision>
      <material name="black"/>
      <geometry>
        <box size="0.0196 0.0275 0.0267"/>
      </geometry>
      <origin xyz="0 0 0.01335"/>
    </collision>
  </link>
  <joint name="joint_11.0" type="revolute">
      <axis xyz="0 1 0"/>
      <limit effort="1" lower="-0.227" upper="1.618" velocity="1"/>
      <parent link="Ring-distal"/>
      <child link="Ring-last"/>
      <origin xyz="0 0 0.0384"/>
  </joint>
  <link name="link_11_0_tip">
    <visual>
      <geometry>
        <mesh filename="AllegroHand/left/sensing_tip.wrl" scale="0.001 0.001 0.001"/>
      </geometry>
      <origin rpy="1.5707963 0 1.5707963" xyz="0.0038 0 0.0142"/>
    </visual>
    <collision>
      <material name="white">
        <color rgba="1 1 1 1"/>
      </material>
      <geometry>
        <box size="0.019 0.023 0.025" />
      </geometry>
      <origin xyz="0.0043 0 0.0079" />
    </collision>
    <collision>
      <material name="white"/>
      <geometry>
        <cylinder length="0.019" radius="0.0115"/>
      </geometry>
      <origin rpy="0 -1.5707963 0" xyz="0.0043 0 0.0204" />
    </collision>
  </link>
  <joint name="joint_11_0_tip" type="fixed">
      <parent link="Ring-last"/>
      <child link="link_11_0_tip"/>
      <origin xyz="0 0 0.0267"/>
  </joint>
  <link name="Medium-base">
    <visual>
      <geometry>
        <mesh filename="AllegroHand/left/link_0_0.wrl" scale="0.001 0.001 0.001"/>
      </geometry>
      <origin xyz="0 0 0.0164"/>
    </visual>
    <collision>
      <material name="black"/>
      <geometry>
        <box size="0.0196 0.0275 0.0164"/>
      </geometry>
      <origin xyz="0 0 0.0082"/>
    </collision>
  </link>
  <joint name="joint_4.0" type="revolute">
      <axis xyz="0 0 1"/>
      <limit effort="1" lower="-0.47" upper="0.47" velocity="1"/>
      <parent link="Palm"/>
      <child link="Medium-base"/>
      <origin xyz="0 0 0.0007"/>
  </joint>
  <link name="Medium-proximal">
    <visual>
      <geometry>
        <mesh filename="AllegroHand/left/link_1_0.wrl" scale="0.001 0.001 0.001"/>
      </geometry>
      <origin rpy="1.5707963 -1.5707963 0"/>
    </visual>
    <collision>
      <material name="black"/>
      <geometry>
        <box size="0.0196 0.0275 0.054"/>
      </geometry>
      <origin xyz="0 0 0.027"/>
    </collision>
  </link>
  <joint name="joint_5.0" type="revolute">
      <limit effort="1" lower="-0.196" upper="1.61" velocity="1"/>
      <axis xyz="0 1 0"/>
      <parent link="Medium-base"/>
      <child link="Medium-proximal"/>
      <origin xyz="0 0 0.0164"/>
  </joint>
  <link name="Medium-distal">
    <visual>
      <geometry>
        <mesh filename="AllegroHand/left/link_2_0.wrl" scale="0.001 0.001 0.001"/>
      </geometry>
      <origin rpy="-1.5707963 -1.5707963 0"/>
    </visual>
    <collision>
      <material name="black"/>
      <geometry>
        <box size="0.0196 0.0275 0.0384"/>
      </geometry>
      <origin xyz="0 0 0.0192"/>
    </collision>
  </link>
  <joint name="joint_6.0" type="revolute">
      <axis xyz="0 1 0"/>
      <limit effort="1" lower="-0.174" upper="1.709" velocity="1"/>
      <parent link="Medium-proximal"/>
      <child link="Medium-distal"/>
      <origin xyz="0 0 0.054"/>
  </joint>
  <link name="Medium-last">
    <visual>
      <geometry>
        <mesh filename="AllegroHand/left/link_3_0.wrl" scale="0.001 0.001 0.001"/>
      </geometry>
      <origin rpy="-1.5707963 -1.5707963 0"/>
    </visual>
    <collision>
      <material name="black"/>
      <geometry>
        <box size="0.0196 0.0275 0.0267"/>
      </geometry>
      <origin xyz="0 0 0.01335"/>
    </collision>
  </link>
  <joint name="joint_7.0" type="revolute">
      <axis xyz="0 1 0"/>
      <limit effort="1" lower="-0.227" upper="1.618" velocity="1"/>
      <parent link="Medium-distal"/>
      <child link="Medium-last"/>
      <origin xyz="0 0 0.0384"/>
  </joint>
  <link name="link_7_0_tip">
    <visual>
      <geometry>
        <mesh filename="AllegroHand/left/sensing_tip.wrl" scale="0.001 0.001 0.001"/>
      </geometry>
      <origin rpy="1.5707963 0 1.5707963" xyz="0.0038 0 0.0142"/>
    </visual>
        <collision>
      <material name="white"/>
      <geometry>
        <box size="0.019 0.023 0.025" />
      </geometry>
      <origin xyz="0.0043 0 0.0079" />
    </collision>
    <collision>
      <material name="white"/>
      <geometry>
        <cylinder length="0.019" radius="0.0115"/>
      </geometry>
      <origin rpy="0 -1.5707963 0" xyz="0.0043 0 0.0204" />
    </collision>
  </link>
  <joint name="joint_7_0_tip" type="fixed">
      <parent link="Medium-last"/>
      <child link="link_7_0_tip"/>
      <origin xyz="0 0 0.0267"/>
  </joint>
  <link name="Index-base">
    <visual>
      <geometry>
        <mesh filename="AllegroHand/left/link_0_0.wrl" scale="0.001 0.001 0.001"/>
      </geometry>
      <origin xyz="0 0 0.0164"/>
    </visual>
    <collision>
      <material name="black"/>
      <geometry>
        <box size="0.0196 0.0275 0.0164"/>
      </geometry>
      <origin xyz="0 0 0.0082"/>
    </collision>
  </link>
  <joint name="joint_0.0" type="revolute">
      <axis xyz="0 0 1"/>
      <limit effort="1" lower="-0.47" upper="0.47" velocity="1"/>
      <parent link="Palm"/>
      <child link="Index-base"/>
      <origin rpy="0.08726646255 0 0" xyz="0 -0.0435 -0.001542"/>
  </joint>
  <link name="Index-proximal">
    <visual>
      <geometry>
        <mesh filename="AllegroHand/left/link_1_0.wrl" scale="0.001 0.001 0.001"/>
      </geometry>
      <origin rpy="1.5707963 -1.5707963 0"/>
    </visual>
    <collision>
      <material name="black"/>
      <geometry>
        <box size="0.0196 0.0275 0.054"/>
      </geometry>
      <origin xyz="0 0 0.027"/>
    </collision>
  </link>
  <joint name="joint_1.0" type="revolute">
      <limit effort="1" lower="-0.196" upper="1.61" velocity="1"/>
      <axis xyz="0 1 0"/>
      <parent link="Index-base"/>
      <child link="Index-proximal"/>
      <origin xyz="0 0 0.0164"/>
  </joint>
  <link name="Index-distal">
    <visual>
      <geometry>
        <mesh filename="AllegroHand/left/link_2_0.wrl" scale="0.001 0.001 0.001"/>
      </geometry>
      <origin rpy="-1.5707963 -1.5707963 0"/>
    </visual>
    <collision>
      <material name="black"/>
      <geometry>
        <box size="0.0196 0.0275 0.0384"/>
      </geometry>
      <origin xyz="0 0 0.0192"/>
    </collision>
  </link>
  <joint name="joint_2.0" type="revolute">
      <axis xyz="0 1 0"/>
      <limit effort="1" lower="-0.174" upper="1.709" velocity="1"/>
      <parent link="Index-proximal"/>
      <child link="Index-distal"/>
      <origin xyz="0 0 0.054"/>
  </joint>
  <link name="Index-last">
    <visual>
      <geometry>
        <mesh filename="AllegroHand/left/link_3_0.wrl" scale="0.001 0.001 0.001"/>
      </geometry>
      <origin rpy="-1.5707963 -1.5707963 0"/>
    </visual>
    <collision>
      <material name="black"/>
      <geometry>
        <box size="0.0196 0.0275 0.0267"/>
      </geometry>
      <origin xyz="0 0 0.01335"/>
    </collision>
  </link>
  <joint name="joint_3.0" type="revolute">
      <axis xyz="0 1 0"/>
      <limit effort="1" lower="-0.227" upper="1.618" velocity="1"/>
      <parent link="Index-distal"/>
      <child link="Index-last"/>
      <origin xyz="0 0 0.0384"/>
  </joint>
  <link name="link_3_0_tip">
    <visual>
      <geometry>
        <mesh filename="AllegroHand/left/sensing_tip.wrl" scale="0.001 0.001 0.001"/>
      </geometry>
      <origin rpy="1.5707963 0 1.5707963" xyz="0.0038 0 0.0142"/>
    </visual>
    <collision>
      <material name="white"/>
      <geometry>
        <box size="0.019 0.023 0.025" />
      </geometry>
      <origin xyz="0.0043 0 0.0079" />
    </collision>
    <collision>
      <material name="white"/>
      <geometry>
        <cylinder length="0.019" radius="0.0115"/>
      </geometry>
      <origin rpy="0 -1.5707963 0" xyz="0.0043 0 0.0204" />
    </collision>
  </link>
  <joint name="joint_3_0_tip" type="fixed">
      <parent link="Index-last"/>
      <child link="link_3_0_tip"/>
      <origin xyz="0 0 0.0267"/>
  </joint>
  <link name="Thumb-base">
    <visual>
      <geometry>
        <mesh filename="AllegroHand/left/link_12_0_left.wrl" scale="0.001 0.001 0.001"/>
      </geometry>
      <origin rpy="-1.570796327 0 -1.570796327" xyz="-0.02775 0 0"/>
    </visual>
    <collision>
      <material name="black"/>
      <geometry>
        <box size="0.0358 0.034 0.0455"/>
      </geometry>
      <origin xyz="-0.0179 0.009 0.0145"/>
    </collision>
  </link>
  <joint name="joint_12.0" type="revolute">
      <axis xyz="1 0 0"/>
      <limit effort="1" lower="0.263" upper="1.396" velocity="1"/>
      <parent link="Palm"/>
      <child link="Thumb-base"/>
    <origin rpy="0 -1.65806278845 1.5707963259" xyz="-0.0182 -0.019333 -0.045987"/>
  </joint>
  <link name="Thumb-proximal">
    <visual>
      <geometry>
        <mesh filename="AllegroHand/left/link_13_0.wrl" scale="0.001 0.001 0.001"/>
      </geometry>
      <origin xyz="0 0 0.016000001" rpy="3.141592654 0 3.141592654"/>
    </visual>
    <collision>
      <material name="black"/>
      <geometry>
        <box size="0.0196 0.0275 0.0177"/>
      </geometry>
      <origin xyz="0 0 0.00885"/>
    </collision>
  </link>
  <joint name="joint_13.0" type="revolute">
      <axis xyz="0 0 -1"/>
      <limit effort="1" lower="-0.105" upper="1.163" velocity="1"/>
      <parent link="Thumb-base"/>
      <child link="Thumb-proximal"/>
      <origin xyz="-0.027 0.005 0.0399"/>
  </joint>
  <link name="Thumb-distal">
    <visual>
      <geometry>
        <mesh filename="AllegroHand/left/link_14_0.wrl" scale="0.001 0.001 0.001"/>
      </geometry>
      <origin rpy="-1.5707963259 -1.5707963259 0"/>
    </visual>
    <collision>
      <material name="black"/>
      <geometry>
        <box size="0.0196 0.0275 0.0514"/>
      </geometry>
      <origin xyz="0 0 0.0257"/>
    </collision>
  </link>
  <joint name="joint_14.0" type="revolute">
      <axis xyz="0 1 0"/>
      <limit effort="1" lower="-0.189" upper="1.644" velocity="1"/>
      <parent link="Thumb-proximal"/>
      <child link="Thumb-distal"/>
      <origin xyz="0 0 0.0177"/>
  </joint>
  <link name="Thumb-last">
    <visual>
      <geometry>
        <mesh filename="AllegroHand/left/link_15_0.wrl" scale="0.001 0.001 0.001"/>
      </geometry>
      <origin rpy="1.5707963259 -1.5707963259 0"/>
    </visual>
    <collision>
      <material name="black"/>
      <geometry>
        <box size="0.0196 0.0275 0.0423"/>
      </geometry>
      <origin xyz="0 0 0.02115"/>
    </collision>
  </link>
  <joint name="joint_15.0" type="revolute">
      <axis xyz="0 1 0"/>
      <limit effort="1" lower="-0.162" upper="1.719" velocity="1"/>
      <parent link="Thumb-distal"/>
      <child link="Thumb-last"/>
      <origin xyz="0 0 0.0514"/>
  </joint>
  <link name="link_15_0_tip">
    <visual>
      <geometry>
        <mesh filename="AllegroHand/right/sensing_tip.wrl" scale="0.001 0.001 0.001"/>
      </geometry>
      <origin rpy="1.5707963 0 1.5707963" xyz="0.0038 0 0.0142"/>
    </visual>
    <collision>
      <material name="white"/>
      <geometry>
        <box size="0.019 0.023 0.025" />
      </geometry>
      <origin xyz="0.0043 0 0.0079" />
    </collision>
    <collision>
      <material name="white"/>
      <geometry>
        <cylinder length="0.019" radius="0.0115"/>
      </geometry>
      <origin rpy="0 -1.5707963 0" xyz="0.0043 0 0.0204" />
    </collision>
  </link>
  <joint name="joint_15_0_tip" type="fixed">
      <parent link="Thumb-last"/>
      <child link="link_15_0_tip"/>
      <origin xyz="0 0 0.0423"/>
  </joint>
</robot>

