<?xml version="1.0"?>
<robot name="yumi_left_arm">

   <!--///////////////////////////////////// LEFT ARM ////////////////////////////////  -->

   <link name="null_base">
     <visual>
       <geometry>
         <cylinder radius="0.001" length="0.001"/>
       </geometry>
      </visual>
      <collision>
      <geometry>
        <cylinder radius="0.001" length="0.001"/>
      </geometry>
     </collision>
    </link>
    
    <joint name="joint_1_l" type="revolute">
      <parent link="null_base"/>
      <child link="link_1_l"/>
      <origin xyz="0.05355 0.07250 0.41492" rpy="0.9781 -0.5716 2.3180"/>
      <axis xyz="0 0 1"/>
      <limit lower="-2.941" upper="2.941" effort="300" velocity="3.142" />
      <dynamics damping="0.5"/>
    </joint>

   <link name="link_1_l">
      <inertial>
        <origin xyz="0 -0.03 0.12"/>
        <mass value="2"/>
        <inertia ixx="0.1"  ixy="0"  ixz="0" iyy="0.1" iyz="0" izz="0.1" />
      </inertial>

      <visual>
        <geometry>
          <mesh filename="YuMi/link_1.stl"/>
        </geometry>
      </visual>

      <collision>
        <origin xyz="-0.003 -0.023 0.069" rpy="1 0.44 0"/>
        <geometry>
          <box size="0.075 0.082 0.08"/>
        </geometry>
      </collision>
      <collision>
        <origin xyz="0 0 0.025"/>
        <geometry>
          <cylinder radius="0.05" length="0.062"/>
        </geometry>
      </collision>
      <collision>
        <origin xyz="0.03 0 0.1" rpy="1.570796327 0 0"/>
        <geometry>
          <cylinder radius="0.055" length="0.156"/>
        </geometry>
      </collision>
    </link>

    <joint name="joint_2_l" type="revolute">
      <parent link="link_1_l"/>
      <child link="link_2_l"/>
      <origin xyz="0.03 0 0.1" rpy="1.571 0 0"/>
      <axis xyz="0 0 1"/>
      <limit lower="-2.505" upper="0.759" effort="300" velocity="3.142" />
      <dynamics damping="0.5"/>
    </joint>

   <link name="link_2_l">
      <inertial>
        <mass value="2"/>
        <inertia ixx="0.1"  ixy="0"  ixz="0" iyy="0.1" iyz="0" izz="0.1" />
      </inertial>

      <visual>
        <geometry>
          <mesh filename="YuMi/link_2.stl"/>
        </geometry>
      </visual>

      <collision>
        <origin xyz="-0.03 0.135 0" rpy="1.570796327 0 0"/>
        <geometry>
          <cylinder radius="0.057" length="0.154"/>
        </geometry>
      </collision>
      <collision>
        <origin xyz="-0.021 0.035 -0.025" rpy="1 0 0.25"/>
        <geometry>
          <box size="0.085 0.082 0.08"/>
        </geometry>
      </collision>
    </link>

    <joint name="joint_7_l" type="revolute">
      <parent link="link_2_l"/>
      <child link="link_3_l"/>
      <origin xyz="-0.03 0.17283 0" rpy="-1.571 0 0"/>
      <axis xyz="0 0 1"/>
      <limit lower="-2.941" upper="2.941" effort="300" velocity="3.142" />
      <dynamics damping="0.5"/>
    </joint>

   <link name="link_3_l">
      <inertial>
        <mass value="2"/>
        <inertia ixx="0.1"  ixy="0"  ixz="0" iyy="0.1" iyz="0" izz="0.1" />
      </inertial>

      <visual>
        <geometry>
          <mesh filename="YuMi/link_3.stl"/>
        </geometry>
      </visual>

      <collision>
        <origin xyz="-0.04188 -0.0005 0.07873" rpy="1.570796327 0 0"/>
        <geometry>
          <cylinder radius="0.053" length="0.1573"/>
        </geometry>
      </collision>
      <collision>
        <origin xyz="-0.0085 -0.0225 0.041" rpy="0.6 -0.55 0"/>
        <geometry>
          <box size="0.09 0.07 0.09"/>
        </geometry>
      </collision>
    </link>

    <joint name="joint_3_l" type="revolute">
      <parent link="link_3_l"/>
      <child link="link_4_l"/>
      <origin xyz="-0.04188 0 0.07873" rpy="1.571 -1.571 0"/>
      <axis xyz="0 0 1"/>
      <limit lower="-2.155" upper="1.396" effort="300" velocity="3.142" />
      <dynamics damping="0.5"/>
    </joint>

   <link name="link_4_l">
      <inertial>
        <mass value="2"/>
        <inertia ixx="0.1"  ixy="0"  ixz="0" iyy="0.1" iyz="0" izz="0.1" />
      </inertial>

      <visual>
        <geometry>
          <mesh filename="YuMi/link_4.stl"/>
        </geometry>
      </visual>

      <collision>
        <origin xyz="0.0405 0.121 0" rpy="1.570796327 0 0"/>
        <geometry>
          <cylinder radius="0.0482" length="0.144"/>
        </geometry>
      </collision>
      <collision>
        <origin xyz="0.026 0.038 -0.024" rpy="0.7 0 -0.35"/>
        <geometry>
          <box size="0.09 0.09 0.07"/>
        </geometry>
      </collision>
    </link>

    <joint name="joint_4_l" type="revolute">
      <parent link="link_4_l"/>
      <child link="link_5_l"/>
      <origin xyz="0.0405 0.16461 0" rpy="-1.571 0 0"/>
      <axis xyz="0 0 1"/>
      <limit lower="-5.061" upper="5.061" effort="300" velocity="6.981" />
      <dynamics damping="0.5"/>
    </joint>

   <link name="link_5_l">
      <inertial>
        <mass value="2"/>
        <inertia ixx="0.1"  ixy="0"  ixz="0" iyy="0.1" iyz="0" izz="0.1" />
      </inertial>

      <visual>
        <geometry>
          <mesh filename="YuMi/link_5.stl"/>
        </geometry>
      </visual>

      <collision>
        <origin xyz="-0.025 -0.05 0.099" rpy="1.570796327 0 0"/>
        <geometry>
          <cylinder radius="0.0348" length="0.041"/>
        </geometry>
      </collision>
      <collision>
        <origin xyz="-0.00511 -0.0397 0.0484" rpy="0.3 -0.4 0"/>
        <geometry>
          <box size="0.073 0.049 0.085"/>
        </geometry>
      </collision>
    </link>

    <joint name="joint_5_l" type="revolute">
      <parent link="link_5_l"/>
      <child link="link_6_l"/>
      <origin xyz="-0.027 0 0.10039" rpy="1.571 0 0"/>
      <axis xyz="0 0 1"/>
      <limit lower="-1.536" upper="2.409" effort="300" velocity="6.981" />
      <dynamics damping="0.5"/>
    </joint>

   <link name="link_6_l">
      <inertial>
        <mass value="2"/>
        <inertia ixx="0.1"  ixy="0"  ixz="0" iyy="0.1" iyz="0" izz="0.1" />
      </inertial>

      <visual>
        <geometry>
          <mesh filename="YuMi/link_6.stl"/>
        </geometry>
      </visual>

      <collision>
        <origin xyz="0.0154 -0.006 -0.012"/>
        <geometry>
          <sphere radius="0.065"/>
        </geometry>
      </collision>
    </link>

    <joint name="joint_6_l" type="revolute">
      <parent link="link_6_l"/>
      <child link="link_7_l"/>
      <origin xyz="0.027 0.029 0" rpy="-1.571 0 0"/>
      <axis xyz="0 0 1"/>
      <limit lower="-3.997" upper="3.997" effort="300" velocity="6.981" />
     <dynamics damping="0.5"/>
    </joint>

   <link name="link_7_l">
      <inertial>
        <mass value="2.2"/>
        <inertia ixx="0.1001"  ixy="0"  ixz="0" iyy="0.1001" iyz="0" izz="0.1001" />
      </inertial>

      <visual>
        <geometry>
          <mesh filename="YuMi/link_7.stl"/>
        </geometry>
      </visual>
      <visual>
        <origin xyz="0 0 0.007" rpy="0 0 3.142" />
        <geometry>
          <mesh filename="YuMi/gripperLeft.dae"/>
        </geometry>
      </visual>

      <collision>
        <origin xyz="0 0 0.0536"/>
        <geometry>
          <box size="0.084 0.069 0.093"/>
        </geometry>
      </collision>
    </link>

    <joint name="gripper_l_joint" type="prismatic">
      <parent link="link_7_l"/>
      <child link="gripper_l_finger_r"/>
      <origin xyz="0 -0.0065 0.0907"/>
      <axis xyz="-1 0 0" />
      <limit lower="0" upper="0.025" effort="300" velocity="0.02" />
      <dynamics damping="0.5"/>
    </joint>

    <link name="gripper_l_finger_r">
      <inertial>
        <mass value="0.01"/>
        <inertia ixx="0.000001"  ixy="0"  ixz="0" iyy="0.000001" iyz="0" izz="0.000001" />
      </inertial>

      <visual>
        <geometry>
          <mesh filename="YuMi/finger.dae"/>
        </geometry>
      </visual>

      <collision>
        <origin xyz="-0.0055 0.0062 0.0297"/>
        <geometry>
          <box size="0.011 0.021 0.045"/>
        </geometry>
      </collision>
    </link>

    <joint name="gripper_l_joint_m" type="prismatic">
      <parent link="link_7_l"/>
      <child link="gripper_l_finger_l"/>
      <origin xyz="0 0.0065 0.0907" rpy="0 0 3.142"/>
      <axis xyz="-1 0 0" />
      <limit lower="0" upper="0.025" effort="300" velocity="0.02" />
      <dynamics damping="0.5"/>
     ! <mimic joint="gripper_l_joint"/> 
    </joint>

    <link name="gripper_l_finger_l">
      <inertial>
        <mass value="0.01"/>
        <inertia ixx="0.000001"  ixy="0"  ixz="0" iyy="0.000001" iyz="0" izz="0.000001" />
      </inertial>

      <visual>
        <geometry>
          <mesh filename="YuMi/finger.dae"/>
        </geometry>
      </visual>

      <collision>
        <origin xyz="-0.0055 0.0062 0.0297"/>
        <geometry>
          <box size="0.011 0.021 0.045"/>
        </geometry>
      </collision>
    </link>
    
</robot>
