<?xml version="1.0"?>
<robot name="Chain">
<link name="base_link">

       <visual>
      <geometry>
	<box size="0.002 0.002 0.001" />
      </geometry>
      <origin rpy="0 1.57 0" xyz="0 0 0"/>
      <material name="black">
        <color rgba="0.5 0.5 1 1"/>
      </material>
    </visual>

    <collision>
      <geometry>
	<box size="0.002 0.002 0.001" />
      </geometry>
      <origin rpy="0 1.57 0" xyz="0 0 0"/>
    </collision>
    <inertial>
	<mass value="5"/>
	<inertia ixx="1.0" ixy="0.0" ixz="0.0" iyy="1.0" iyz="0.0" izz="1.0"/>
    </inertial>
  </link>


   <link name="link1">
    <visual>
      <geometry>
	<box size="0.003 0.0005 0.0005" />
      </geometry>
      <origin rpy="0 1.57 0" xyz="0.0021 0 0 "/>
      <material name="red">
        <color rgba="1 0 0 1"/>
      </material>
    </visual>
    <collision>
      <geometry>
	<box size="0.003 0.0005 0.0005" />

      </geometry>
      <origin rpy="0 1.57 0" xyz="0.0021 0 0 "/>
    </collision>
    <inertial>
	<mass value="1"/>
	<inertia ixx="1.0" ixy="0.0" ixz="0.0" iyy="1.0" iyz="0.0" izz="1.0"/>
    </inertial>
  </link>

<link name="link2">
    <visual>
      <geometry>
	<box size="0.003 0.0005 0.0005" />
      </geometry>
  <origin rpy="0 1.57 0" xyz="0.0021 0 0"/>
      <material name="blue">
        <color rgba="0 0 1 1"/>
      </material>
    </visual>
    <collision>
      <geometry>
	<box size="0.003 0.0005 0.0005" />
      </geometry>
  <origin rpy="0 1.57 0" xyz="0.0021 0 0"/>
    </collision>
    <inertial>
	<mass value="1"/>
	<inertia ixx="1.0" ixy="0.0" ixz="0.0" iyy="1.0" iyz="0.0" izz="1.0"/>
    </inertial>
  </link>
  


<link name="gripper">
    <visual>
      <geometry>
	<box size="0.0007 0.0002 0.0002" />
      </geometry>
      <origin rpy="0 0 1.57" xyz="0.001 0 0"/>
      <material name="white">
        <color rgba="0.5 0.5 0.5 1"/>
      </material>
    </visual>
    <collision>
      <geometry>
	<box size="0.0007 0.0002 0.0002" />
      </geometry>
      <origin rpy="0 0 1.57" xyz="0.0007 0 0"/>
    </collision>
    <inertial>
	<mass value="0.5"/>
	<inertia ixx="1.0" ixy="0.0" ixz="0.0" iyy="1.0" iyz="0.0" izz="1.0"/>
    </inertial>
  </link>

  <joint name="joint1" type="revolute">
    <parent link="base_link"/>
    <child link="link1"/>
    <origin xyz="0.002 0 0"/>
    <axis xyz="0 0 1" />
    <limit effort="300" velocity="0.1" lower="-1.55" upper="1.55"/>
    <dynamics damping="50" friction="1"/>
  </joint>

<joint name="joint2" type="revolute">
    <parent link="link1"/>
    <child link="link2"/>
    <origin xyz="0.003 0 0"/>
    <axis xyz="0 0 1" />
    <limit effort="300" velocity="0.1" lower="-1.50" upper="1.50"/>
    <dynamics damping="50" friction="1"/>
  </joint>

<joint name="joint3" type="revolute">
    <parent link="link2"/>
    <child link="gripper"/>
    <origin xyz="0.0025 0 0"/>
    <axis xyz="0 0 1" />
    <limit effort="300" velocity="0.1" lower="-1" upper="1"/>
    <dynamics damping="50" friction="1"/>
  </joint>

  
  </robot>
